Workbook

Sheet 使い方
A1: 年最高外気温度の極値統計解析（再現期間100年） ― 使い方 ―
B3: 目的 | C3: 気象庁が公開している「年最高気温」の観測記録に極値統計（ワイブル分布）をあてはめ、再現期間 100 年に相当する年最高外気温度（100年に1回程度の確率で起こる猛暑の気温）を求めます。空調負荷計算・設備機器の耐熱設計・屋外構造物の温度応力検討などの設計用外気温度の設定に使います。
B4: 使う順序 | C4: ① 「データ入力」シートに 年 と 年最高気温(℃) を貼り付ける ② 「結果」シートの上部に 再現期間100年の年最高外気温度 が表示される ③ 「極値統計計算」シートで分布パラメータ・相関係数（あてはまりの良さ）を確認する ※ 数式はすべて生きています。データを入れ替えれば自動的に再計算されます。
B5: 気象庁データの取り方 | C5: 【方法A：過去の気象データ検索（年ごとの値）】 https://www.data.jma.go.jp/obd/stats/etrn/index.php → 地点を選ぶ → 「年ごとの値を表示」 → 表の『最高気温(℃)／最高』の列が年最高気温です。 【方法B：過去の気象データ・ダウンロード（CSV）】 https://www.data.jma.go.jp/risk/obsdl/index.php → 地点を選ぶ → 項目を選ぶ →『年別値』→『最高気温の最高』→ CSVをダウンロード → CSV は Shift_JIS。Excelで開き、年 と 気温 の2列を「データ入力」に貼り付け。 ※ CSVには品質情報（均質番号・現象なし情報）の列が付きます。値が不完全な年は除いてください。
B6: 計算方法（本ブックの中身） | C6: ① 標本を降順に並べ、順位 m を付ける（m=1 が最大値） ② 非超過確率 F をワイブルのプロッティング・ポジション F = 1 − m/(n+1) で与える （再現期間は T = 1/(1−F) = (n+1)/m） ③ ワイブル分布（第III種極値分布・上限型）を最小二乗であてはめる F(x) = exp[ −((ω−x)/a)^k ] x ≦ ω ln(−ln F) = k·ln(ω−x) − k·ln a … ω を仮定すると直線になる → ω を2段階のグリッド探索で振り、相関係数 r が最大になる ω を採用 → 傾き k（形状）と切片から a（尺度）を決定 ④ 再現期間 T の値： x(T) = ω − a·[ −ln(1 − 1/T) ]^(1/k) ⑤ 検証用に グンベル分布（第I種極値分布）も併記 F(x)=exp[−exp(−(x−β)/α)] x(T) = β + α·[ −ln(−ln(1−1/T)) ]
B7: なぜワイブル（第III種）か | C7: 気温には物理的な上限が存在すると考えられるため、上に有界な第III種極値分布（逆ワイブル分布）は年最高気温に適した形をしています。 形状母数 k が大きく、ω が標本最大値からかけ離れて大きくなる場合、分布はグンベル分布（k→∞ の極限）に漸近しています。その場合はグンベルの値を採用してください。「極値統計計算」シートに自動判定を表示します。
B8: 結果を使うときの注意 | C8: ・標本数 n：n≧30、できれば n≧50 を推奨します。n が小さいまま 100 年を外挿すると誤差が大きくなります（「結果」シートに 95%信頼区間の目安を表示）。 ・温暖化トレンド：極値統計は「母集団が変わらない（定常）」ことを前提にします。昇温トレンドがある地点では過去の長期データをそのまま使うと過小評価になります。直近30〜50年に期間を絞る、あるいはトレンド補正した値を入力してください。（「データ入力」シートに経年変化グラフと回帰トレンドを表示します） ・観測所の移転・周辺環境の変化（都市化・ヒートアイランド）があると系列が不連続になります。気象庁の観測所メタデータで移転履歴を確認してください。 ・ここで求まるのは「観測露場の気温」です。建物周辺の実効的な外気温は日射・輻射・排熱の影響で数℃高くなることがあります。設計値には別途割増しを検討してください。 ・空調設計では TAC 温度（超過確率を許容する設計外気温）など別の考え方もあります。用途に応じて使い分けてください。
B9: シート構成 | C9: 使い方 … このシート データ入力 … 年 と 年最高気温を入れる（黄色いセルが入力欄） 極値統計計算 … 順位統計・確率プロット・ω探索・分布母数の算出（通常は触らない） 結果 … 再現期間表・確率プロット・再現期間曲線 サンプルデータ… 動作確認用のダミー標本の控え（実測値ではありません）
B10: 記号 | C10: n：標本数（年数） m：降順順位 x(m)：m番目に大きい年最高気温 F：非超過確率 T：再現期間(年) ω：上限母数(℃) a：尺度母数(℃) k：形状母数 α：グンベル尺度母数(℃) β：グンベル位置母数(℃) r：確率プロット上の相関係数
B12: 重要 | C12: 出荷時の「データ入力」シートには動作確認用のダミー値が入っています。気象庁の実測値に必ず置き換えてください。ダミーのままの結果は設計に使えません。

Sheet データ入力
A1: データ入力 ― 気象庁の年最高気温を貼り付けてください ―
A2: ⚠ 現在入っている値は動作確認用のダミーです。気象庁の実測値に置き換えてください（黄色いセルが入力欄）。行が足りない場合は 211 行目までのどこかに追記してください。
D3: 標本統計量（自動計算）
A4: 観測地点名 | B4: （ダミー）東京 相当 | D4: 平均 (℃) | E4: =IFERROR(AVERAGE(データ入力!$B$12:$B$211),"") -> 35.132
A5: 観測所番号 | B5: （ダミー）47662 相当 | D5: 標準偏差 (℃) | E5: =IFERROR(STDEV(データ入力!$B$12:$B$211),"") -> 1.5037035
A6: データ出典 | B6: ※ダミーデータ／実データは気象庁 過去の気象データ検索に置換 | D6: 最大 (℃) | E6: =IFERROR(MAX(データ入力!$B$12:$B$211),"") -> 39.4
A7: 統計期間 | B7: =IF(B8=0,"データを入力してください",TEXT(MIN(データ入力!$A$12:$A$211),"0")&" 〜 "&TEXT(MAX(データ入力!$A$12:$A$211),"0")&" （"&B8&"年間）") -> 1950 〜 2024 （75年間） | D7: 最大値の年 | E7: =IFERROR(INDEX(データ入力!$A$12:$A$211,MATCH(MAX(データ入力!$B$12:$B$211),データ入力!$B$12:$B$211,0)),"") -> 1983
A8: 標本数 n | B8: =COUNT(データ入力!$B$12:$B$211) -> 75 | C8: ← 年最高気温が入力されている年数（自動） | D8: 最小 (℃) | E8: =IFERROR(MIN(データ入力!$B$12:$B$211),"") -> 32.4
A9: 標本数の判定 | B9: =IF(B8=0,"データを入力してください",IF(B8<10,"× n<10：極値解析には不足しています",IF(B8<30,"△ n<30：100年再現値の信頼性は低い（参考値扱い）",IF(B8<50,"○ n≧30：概ね実用可（n≧50を推奨）","◎ n≧50：良好")))) -> ◎ n≧50：良好 | D9: トレンド (℃/年) | E9: =IFERROR(SLOPE(データ入力!$B$12:$B$211,データ入力!$A$12:$A$211),"") -> 0.028153627
D10: 100年あたり (℃) | E10: =IFERROR(E9*100,"") -> 2.8153627
A11: 年 | B11: 年最高気温 (℃) | C11: 備考 | I11: ※ グラフの縦軸が 0 から始まる場合は、縦軸を右クリック →［軸の書式設定］で最小値を調整してください。
A12: 1950 | B12: 36 | C12: ダミー
A13: 1951 | B13: 33.3
A14: 1952 | B14: 33
A15: 1953 | B15: 34.7
A16: 1954 | B16: 34.9
A17: 1955 | B17: 34.4
A18: 1956 | B18: 35.6
A19: 1957 | B19: 32.7
A20: 1958 | B20: 33.2
A21: 1959 | B21: 33
A22: 1960 | B22: 35
A23: 1961 | B23: 35.5
A24: 1962 | B24: 33.8
... A86: 2024 | B86: 38.3

Sheet 極値統計計算
A1: 極値統計計算（順位統計・確率プロット・分布母数の推定）
A2: このシートは自動計算です。通常は編集しないでください。灰色の列（T〜AD）は上限母数 ω を探索するための作業領域です。
A4: 【順位統計表】降順に並べ替え、ワイブルのプロッティング・ポジションを与える | M4: 【1】グンベル分布（第I種極値分布）― 確率プロット最小二乗法 | Q4: 【ω グリッド探索の設定】 | T4: 【第1段】粗い探索 | Z4: 【第2段】細かい探索 | AF4: 【適合曲線の描画用】
M5: x = β + α·u u = −ln(−ln F) | Q5: 第1段 刻み Δ1 (℃) | R5: 0.5
A6: 順位 m | B6: 有効 | C6: x(m) 降順 (℃) | D6: 対応年(参考) | E6: F = 1−m/(n+1) | F6: T = 1/(1−F) | G6: u = −ln(−ln F) | H6: y = ln(−ln F) | I6: 残差 グンベル | J6: 残差 ワイブル | M6: Σx | N6: =SUMPRODUCT($B$7:$B$206,$C$7:$C$206) -> 2634.9 | Q6: 探索下限 ω_min (℃) | R6: =IFERROR(MAX(データ入力!$B$12:$B$211)+0.05,"") -> 39.45 | T6: ω 候補 (℃) | U6: Σ ln(ω−x) | V6: Σ [ln(ω−x)]² | W6: Σ y·ln(ω−x) | X6: 相関係数 r | Z6: ω 候補 (℃) | AA6: Σ ln(ω−x) | AB6: Σ [ln(ω−x)]² | AC6: Σ y·ln(ω−x) | AD6: 相関係数 r | AF6: u | AG6: グンベル適合 (℃) | AH6: ワイブル適合 (℃) | AI6: T (年)
A7: 1 | B7: =IF($A7<=データ入力!$B$8,1,0) -> 1 | C7: =IF($B7=1,LARGE(データ入力!$B$12:$B$211,$A7),0) -> 39.4 | D7: =IF($B7=1,IFERROR(INDEX(データ入力!$A$12:$A$211,MATCH($C7,データ入力!$B$12:$B$211,0)),""),"") -> 1983 | E7: =IF($B7=1,1-$A7/(データ入力!$B$8+1),0) -> 0.98684211 | F7: =IF($B7=1,(データ入力!$B$8+1)/$A7,"") -> 76 | G7: =IF($B7=1,-LN(-LN($E7)),0) -> 4.324118 | H7: =IF($B7=1,LN(-LN($E7)),0) -> -4.324118 | I7: =IF($B7=1,IFERROR($C7-($N$10+$N$9*$G7),""),"") -> -0.44357832 | J7: =IF($B7=1,IFERROR($C7-($N$21-$N$26*EXP(-$G7/$N$24)),""),"") -> -0.17676996 | M7: Σu | N7: =SUMPRODUCT($B$7:$B$206,$G$7:$G$206) -> 41.691505 | Q7: 探索上限 (℃) | R7: =IFERROR($R$6+$R$5*(200-1),"") -> 138.95 | T7: =IFERROR($R$6+($A7-1)*$R$5,"") -> 39.45 | U7: =IFERROR(SUMPRODUCT($B$7:$B$206,LN($T7-$C$7:$C$206)),"") -> 100.23724 | V7: =IFERROR(SUMPRODUCT($B$7:$B$206,LN($T7-$C$7:$C$206),LN($T7-$C$7:$C$206)),"") -> 169.49764 | W7: =IFERROR(SUMPRODUCT($B$7:$B$206,LN($T7-$C$7:$C$206),$H$7:$H$206),"") -> -3.2022015 | X7: =IFERROR((データ入力!$B$8*W7-U7*$N$22)/SQRT((データ入力!$B$8*V7-U7^2)*(データ入力!$B$8*$N$23-$N$22^2)),-1) -> 0.85506027 | Z7: =IFERROR($R$10+($A7-1)*$R$9,"") -> 58.95 | AA7: =IFERROR(SUMPRODUCT($B$7:$B$206,LN($Z7-$C$7:$C$206)),"") -> 237.63078 | AB7: =IFERROR(SUMPRODUCT($B$7:$B$206,LN($Z7-$C$7:$C$206),LN($Z7-$C$7:$C$206)),"") -> 753.22183 | AC7: =IFERROR(SUMPRODUCT($B$7:$B$206,LN($Z7-$C$7:$C$206),$H$7:$H$206),"") -> -126.37606 | AD7: =IFERROR((データ入力!$B$8*AC7-AA7*$N$22)/SQRT((データ入力!$B$8*AB7-AA7^2)*(データ入力!$B$8*$N$23-$N$22^2)),-1) -> 0.99702654 | AF7: -2 | AG7: =IFERROR($N$10+$N$9*$AF7,"") -> 31.936267 | AH7: =IFERROR($N$21-$N$26*EXP(-$AF7/$N$24),"") -> 31.65546 | AI7: =IFERROR(1/(1-EXP(-EXP(-$AF7))),"") -> 1.0006184
A8: 2 | B8: =IF($A8<=データ入力!$B$8,1,0) -> 1 | C8: =IF($B8=1,LARGE(データ入力!$B$12:$B$211,$A8),0) -> 39.1 | D8: =IF($B8=1,IFERROR(INDEX(データ入力!$A$12:$A$211,MATCH($C8,データ入力!$B$12:$B$211,0)),""),"") -> 2009 | E8: =IF($B8=1,1-$A8/(データ入力!$B$8+1),0) -> 0.97368421 | F8: =IF($B8=1,(データ入力!$B$8+1)/$A8,"") -> 38 | G8: =IF($B8=1,-LN(-LN($E8)),0) -> 3.6242817 | H8: =IF($B8=1,LN(-LN($E8)),0) -> -3.6242817 | I8: =IF($B8=1,IFERROR($C8-($N$10+$N$9*$G8),""),"") -> 0.13145657 | J8: =IF($B8=1,IFERROR($C8-($N$21-$N$26*EXP(-$G8/$N$24)),""),"") -> 0.27494178 | M8: Σu² | N8: =SUMPRODUCT($B$7:$B$206,$G$7:$G$206,$G$7:$G$206) -> 129.35073 | Q8: 第1段の最良 ω (℃) | R8: =IFERROR(INDEX($T$7:$T$206,MATCH(MAX($X$7:$X$206),$X$7:$X$206,0)),"") -> 59.45 | T8: =IFERROR($R$6+($A8-1)*$R$5,"") -> 39.95 | U8: =IFERROR(SUMPRODUCT($B$7:$B$206,LN($T8-$C$7:$C$206)),"") -> 112.37265 | V8: =IFERROR(SUMPRODUCT($B$7:$B$206,LN($T8-$C$7:$C$206),LN($T8-$C$7:$C$206)),"") -> 183.32789 | W8: =IFERROR(SUMPRODUCT($B$7:$B$206,LN($T8-$C$7:$C$206),$H$7:$H$206),"") -> -24.734129 | X8: =IFERROR((データ入力!$B$8*W8-U8*$N$22)/SQRT((データ入力!$B$8*V8-U8^2)*(データ入力!$B$8*$N$23-$N$22^2)),-1) -> 0.94676176 | Z8: =IFERROR($R$10+($A8-1)*$R$9,"") -> 58.955025 | AA8: =IFERROR(SUMPRODUCT($B$7:$B$206,LN($Z8-$C$7:$C$206)),"") -> 237.64667 | AB8: =IFERROR(SUMPRODUCT($B$7:$B$206,LN($Z8-$C$7:$C$206),LN($Z8-$C$7:$C$206)),"") -> 753.32237 | AC8: =IFERROR(SUMPRODUCT($B$7:$B$206,LN($Z8-$C$7:$C$206),$H$7:$H$206),"") -> -126.38613 | AD8: =IFERROR((データ入力!$B$8*AC8-AA8*$N$22)/SQRT((データ入力!$B$8*AB8-AA8^2)*(データ入力!$B$8*$N$23-$N$22^2)),-1) -> 0.99702655 | AF8: -1.8 | AG8: =IFERROR($N$10+$N$9*$AF8,"") -> 32.186336 | AH8: =IFERROR($N$21-$N$26*EXP(-$AF8/$N$24),"") -> 31.948742 | AI8: =IFERROR(1/(1-EXP(-EXP(-$AF8))),"") -> 1.0023643
A9: 3 | B9: =IF($A9<=データ入力!$B$8,1,0) -> 1 | C9: =IF($B9=1,LARGE(データ入力!$B$12:$B$211,$A9),0) -> 38.5 | D9: =IF($B9=1,IFERROR(INDEX(データ入力!$A$12:$A$211,MATCH($C9,データ入力!$B$12:$B$211,0)),""),"") -> 1978 | E9: =IF($B9=1,1-$A9/(データ入力!$B$8+1),0) -> 0.96052632 | F9: =IF($B9=1,(データ入力!$B$8+1)/$A9,"") -> 25.333333 | G9: =IF($B9=1,-LN(-LN($E9)),0) -> 3.2120517 | H9: =IF($B9=1,LN(-LN($E9)),0) -> -3.2120517 | I9: =IF($B9=1,IFERROR($C9-($N$10+$N$9*$G9),""),"") -> 0.046885082 | J9: =IF($B9=1,IFERROR($C9-($N$21-$N$26*EXP(-$G9/$N$24)),""),"") -> 0.13095566 | M9: 尺度母数 α (℃) | N9: =IFERROR((データ入力!$B$8*SUMPRODUCT($B$7:$B$206,$C$7:$C$206,$G$7:$G$206)-N6*N7)/(データ入力!$B$8*N8-N7^2),"") -> 1.2503421 | Q9: 第2段 刻み Δ2 (℃) | R9: =IFERROR(2*$R$5/(200-1),"") -> 0.0050251256 | T9: =IFERROR($R$6+($A9-1)*$R$5,"") -> 40.45 | U9: =IFERROR(SUMPRODUCT($B$7:$B$206,LN($T9-$C$7:$C$206)),"") -> 121.22091 | V9: =IFERROR(SUMPRODUCT($B$7:$B$206,LN($T9-$C$7:$C$206),LN($T9-$C$7:$C$206)),"") -> 206.11384 | W9: =IFERROR(SUMPRODUCT($B$7:$B$206,LN($T9-$C$7:$C$206),$H$7:$H$206),"") -> -35.598693 | X9: =IFERROR((データ入力!$B$8*W9-U9*$N$22)/SQRT((データ入力!$B$8*V9-U9^2)*(データ入力!$B$8*$N$23-$N$22^2)),-1) -> 0.96650928 | Z9: =IFERROR($R$10+($A9-1)*$R$9,"") -> 58.96005 | AA9: =IFERROR(SUMPRODUCT($B$7:$B$206,LN($Z9-$C$7:$C$206)),"") -> 237.66255 | AB9: =IFERROR(SUMPRODUCT($B$7:$B$206,LN($Z9-$C$7:$C$206),LN($Z9-$C$7:$C$206)),"") -> 753.4229 | AC9: =IFERROR(SUMPRODUCT($B$7:$B$206,LN($Z9-$C$7:$C$206),$H$7:$H$206),"") -> -126.39621 | AD9: =IFERROR((データ入力!$B$8*AC9-AA9*$N$22)/SQRT((データ入力!$B$8*AB9-AA9^2)*(データ入力!$B$8*$N$23-$N$22^2)),-1) -> 0.99702656 | AF9: -1.6 | AG9: =IFERROR($N$10+$N$9*$AF9,"") -> 32.436404 | AH9: =IFERROR($N$21-$N$26*EXP(-$AF9/$N$24),"") -> 32.238932 | AI9: =IFERROR(1/(1-EXP(-EXP(-$AF9))),"") -> 1.0071122
A10: 4 | B10: =IF($A10<=データ入力!$B$8,1,0) -> 1 | C10: =IF($B10=1,LARGE(データ入力!$B$12:$B$211,$A10),0) -> 38.3 | D10: =IF($B10=1,IFERROR(INDEX(データ入力!$A$12:$A$211,MATCH($C10,データ入力!$B$12:$B$211,0)),""),"") -> 2024 | E10: =IF($B10=1,1-$A10/(データ入力!$B$8+1),0) -> 0.94736842 | F10: =IF($B10=1,(データ入力!$B$8+1)/$A10,"") -> 19 | G10: =IF($B10=1,-LN(-LN($E10)),0) -> 2.9175272 | H10: =IF($B10=1,LN(-LN($E10)),0) -> -2.9175272 | I10: =IF($B10=1,IFERROR($C10-($N$10+$N$9*$G10),""),"") -> 0.21514149 | J10: =IF($B10=1,IFERROR($C10-($N$21-$N$26*EXP(-$G10/$N$24)),""),"") -> 0.26291927 | M10: 位置母数 β (℃) | N10: =IFERROR((N6-N9*N7)/データ入力!$B$8,"") -> 34.436951 | Q10: 第2段 探索下限 (℃) | R10: =IFERROR(MAX($R$8-$R$5,$R$6),"") -> 58.95 | T10: =IFERROR($R$6+($A10-1)*$R$5,"") -> 40.95 | U10: =IFERROR(SUMPRODUCT($B$7:$B$206,LN($T10-$C$7:$C$206)),"") -> 128.8409 | V10: =IFERROR(SUMPRODUCT($B$7:$B$206,LN($T10-$C$7:$C$206),LN($T10-$C$7:$C$206)),"") -> 228.9819 | W10: =IFERROR(SUMPRODUCT($B$7:$B$206,LN($T10-$C$7:$C$206),$H$7:$H$206),"") -> -43.801754 | X10: =IFERROR((データ入力!$B$8*W10-U10*$N$22)/SQRT((データ入力!$B$8*V10-U10^2)*(データ入力!$B$8*$N$23-$N$22^2)),-1) -> 0.97619155 | Z10: =IFERROR($R$10+($A10-1)*$R$9,"") -> 58.965075 | AA10: =IFERROR(SUMPRODUCT($B$7:$B$206,LN($Z10-$C$7:$C$206)),"") -> 237.67844 | AB10: =IFERROR(SUMPRODUCT($B$7:$B$206,LN($Z10-$C$7:$C$206),LN($Z10-$C$7:$C$206)),"") -> 753.52341 | AC10: =IFERROR(SUMPRODUCT($B$7:$B$206,LN($Z10-$C$7:$C$206),$H$7:$H$206),"") -> -126.40628 | AD10: =IFERROR((データ入力!$B$8*AC10-AA10*$N$22)/SQRT((データ入力!$B$8*AB10-AA10^2)*(データ入力!$B$8*$N$23-$N$22^2)),-1) -> 0.99702657 | AF10: -1.4 | AG10: =IFERROR($N$10+$N$9*$AF10,"") -> 32.686472 | AH10: =IFERROR($N$21-$N$26*EXP(-$AF10/$N$24),"") -> 32.526062 | AI10: =IFERROR(1/(1-EXP(-EXP(-$AF10))),"") -> 1.0176377
A11: 5 | B11: =IF($A11<=データ入力!$B$8,1,0) -> 1 | C11: =IF($B11=1,LARGE(データ入力!$B$12:$B$211,$A11),0) -> 37.6 | D11: =IF($B11=1,IFERROR(INDEX(データ入力!$A$12:$A$211,MATCH($C11,データ入力!$B$12:$B$211,0)),""),"") -> 1988 | E11: =IF($B11=1,1-$A11/(データ入力!$B$8+1),0) -> 0.93421053 | F11: =IF($B11=1,(データ入力!$B$8+1)/$A11,"") -> 15.2 | G11: =IF($B11=1,-LN(-LN($E11)),0) -> 2.6874617 | H11: =IF($B11=1,LN(-LN($E11)),0) -> -2.6874617 | I11: =IF($B11=1,IFERROR($C11-($N$10+$N$9*$G11),""),"") -> -0.19719791 | J11: =IF($B11=1,IFERROR($C11-($N$21-$N$26*EXP(-$G11/$N$24)),""),"") -> -0.17414061 | M11: 相関係数 r | N11: =IFERROR((データ入力!$B$8*SUMPRODUCT($B$7:$B$206,$C$7:$C$206,$G$7:$G$206)-N6*N7)/SQRT((データ入力!$B$8*N8-N7^2)*(データ入力!$B$8*SUMPRODUCT($B$7:$B$206,$C$7:$C$206,$C$7:$C$206)-N6^2)),"") -> 0.9960058 | T11: =IFERROR($R$6+($A11-1)*$R$5,"") -> 41.45 | U11: =IFERROR(SUMPRODUCT($B$7:$B$206,LN($T11-$C$7:$C$206)),"") -> 135.62758 | V11: =IFERROR(SUMPRODUCT($B$7:$B$206,LN($T11-$C$7:$C$206),LN($T11-$C$7:$C$206)),"") -> 251.30425 | W11: =IFERROR(SUMPRODUCT($B$7:$B$206,LN($T11-$C$7:$C$206),$H$7:$H$206),"") -> -50.528128 | X11: =IFERROR((データ入力!$B$8*W11-U11*$N$22)/SQRT((データ入力!$B$8*V11-U11^2)*(データ入力!$B$8*$N$23-$N$22^2)),-1) -> 0.98192231 | Z11: =IFERROR($R$10+($A11-1)*$R$9,"") -> 58.970101 | AA11: =IFERROR(SUMPRODUCT($B$7:$B$206,LN($Z11-$C$7:$C$206)),"") -> 237.69431 | AB11: =IFERROR(SUMPRODUCT($B$7:$B$206,LN($Z11-$C$7:$C$206),LN($Z11-$C$7:$C$206)),"") -> 753.62391 | AC11: =IFERROR(SUMPRODUCT($B$7:$B$206,LN($Z11-$C$7:$C$206),$H$7:$H$206),"") -> -126.41634 | AD11: =IFERROR((データ入力!$B$8*AC11-AA11*$N$22)/SQRT((データ入力!$B$8*AB11-AA11^2)*(データ入力!$B$8*$N$23-$N$22^2)),-1) -> 0.99702658 | AF11: -1.2 | AG11: =IFERROR($N$10+$N$9*$AF11,"") -> 32.936541 | AH11: =IFERROR($N$21-$N$26*EXP(-$AF11/$N$24),"") -> 32.810164 | AI11: =IFERROR(1/(1-EXP(-EXP(-$AF11))),"") -> 1.0375043
A12: 6 | B12: =IF($A12<=データ入力!$B$8,1,0) -> 1 | C12: =IF($B12=1,LARGE(データ入力!$B$12:$B$211,$A12),0) -> 37.5 | D12: =IF($B12=1,IFERROR(INDEX(データ入力!$A$12:$A$211,MATCH($C12,データ入力!$B$12:$B$211,0)),""),"") -> 2023 | E12: =IF($B12=1,1-$A12/(データ入力!$B$8+1),0) -> 0.92105263 | F12: =IF($B12=1,(データ入力!$B$8+1)/$A12,"") -> 12.666667 | G12: =IF($B12=1,-LN(-LN($E12)),0) -> 2.4981366 | H12: =IF($B12=1,LN(-LN($E12)),0) -> -2.4981366 | I12: =IF($B12=1,IFERROR($C12-($N$10+$N$9*$G12),""),"") -> -0.060476821 | J12: =IF($B12=1,IFERROR($C12-($N$21-$N$26*EXP(-$G12/$N$24)),""),"") -> -0.055344407 | T12: =IFERROR($R$6+($A12-1)*$R$5,"") -> 41.95 | U12: =IFERROR(SUMPRODUCT($B$7:$B$206,LN($T12-$C$7:$C$206)),"") -> 141.77906 | V12: =IFERROR(SUMPRODUCT($B$7:$B$206,LN($T12-$C$7:$C$206),LN($T12-$C$7:$C$206)),"") -> 272.94347 | W12: =IFERROR(SUMPRODUCT($B$7:$B$206,LN($T12-$C$7:$C$206),$H$7:$H$206),"") -> -56.271294 | X12: =IFERROR((データ入力!$B$8*W12-U12*$N$22)/SQRT((データ入力!$B$8*V12-U12^2)*(データ入力!$B$8*$N$23-$N$22^2)),-1) -> 0.98565547 | Z12: =IFERROR($R$10+($A12-1)*$R$9,"") -> 58.975126 | AA12: =IFERROR(SUMPRODUCT($B$7:$B$206,LN($Z12-$C$7:$C$206)),"") -> 237.71019 | AB12: =IFERROR(SUMPRODUCT($B$7:$B$206,LN($Z12-$C$7:$C$206),LN($Z12-$C$7:$C$206)),"") -> 753.7244 | AC12: =IFERROR(SUMPRODUCT($B$7:$B$206,LN($Z12-$C$7:$C$206),$H$7:$H$206),"") -> -126.42641 | AD12: =IFERROR((データ入力!$B$8*AC12-AA12*$N$22)/SQRT((データ入力!$B$8*AB12-AA12^2)*(データ入力!$B$8*$N$23-$N$22^2)),-1) -> 0.99702659 | AF12: -1 | AG12: =IFERROR($N$10+$N$9*$AF12,"") -> 33.186609 | AH12: =IFERROR($N$21-$N$26*EXP(-$AF12/$N$24),"") -> 33.09127 | AI12: =IFERROR(1/(1-EXP(-EXP(-$AF12))),"") -> 1.0706501
A13: 7 | B13: =IF($A13<=データ入力!$B$8,1,0) -> 1 | C13: =IF($B13=1,LARGE(データ入力!$B$12:$B$211,$A13),0) -> 37.2 | D13: =IF($B13=1,IFERROR(INDEX(データ入力!$A$12:$A$211,MATCH($C13,データ入力!$B$12:$B$211,0)),""),"") -> 2005 | E13: =IF($B13=1,1-$A13/(データ入力!$B$8+1),0) -> 0.90789474 | F13: =IF($B13=1,(データ入力!$B$8+1)/$A13,"") -> 10.857143 | G13: =IF($B13=1,-LN(-LN($E13)),0) -> 2.3368988 | H13: =IF($B13=1,LN(-LN($E13)),0) -> -2.3368988 | I13: =IF($B13=1,IFERROR($C13-($N$10+$N$9*$G13),""),"") -> -0.15887437 | J13: =IF($B13=1,IFERROR($C13-($N$21-$N$26*EXP(-$G13/$N$24)),""),"") -> -0.16726853 | M13: 【2】グンベル分布 ― 積率法（参考・検算用） | T13: =IFERROR($R$6+($A13-1)*$R$5,"") -> 42.45 | U13: =IFERROR(SUMPRODUCT($B$7:$B$206,LN($T13-$C$7:$C$206)),"") -> 147.4197 | V13: =IFERROR(SUMPRODUCT($B$7:$B$206,LN($T13-$C$7:$C$206),LN($T13-$C$7:$C$206)),"") -> 293.87981 | W13: =IFERROR(SUMPRODUCT($B$7:$B$206,LN($T13-$C$7:$C$206),$H$7:$H$206),"") -> -61.299106 | X13: =IFERROR((データ入力!$B$8*W13-U13*$N$22)/SQRT((データ入力!$B$8*V13-U13^2)*(データ入力!$B$8*$N$23-$N$22^2)),-1) -> 0.9882381 | Z13: =IFERROR($R$10+($A13-1)*$R$9,"") -> 58.980151 | AA13: =IFERROR(SUMPRODUCT($B$7:$B$206,LN($Z13-$C$7:$C$206)),"") -> 237.72606 | AB13: =IFERROR(SUMPRODUCT($B$7:$B$206,LN($Z13-$C$7:$C$206),LN($Z13-$C$7:$C$206)),"") -> 753.82487 | AC13: =IFERROR(SUMPRODUCT($B$7:$B$206,LN($Z13-$C$7:$C$206),$H$7:$H$206),"") -> -126.43647 | AD13: =IFERROR((データ入力!$B$8*AC13-AA13*$N$22)/SQRT((データ入力!$B$8*AB13-AA13^2)*(データ入力!$B$8*$N$23-$N$22^2)),-1) -> 0.9970266 | AF13: -0.8 | AG13: =IFERROR($N$10+$N$9*$AF13,"") -> 33.436678 | AH13: =IFERROR($N$21-$N$26*EXP(-$AF13/$N$24),"") -> 33.369412 | AI13: =IFERROR(1/(1-EXP(-EXP(-$AF13))),"") -> 1.1210875
A14: 8 | B14: =IF($A14<=データ入力!$B$8,1,0) -> 1 | C14: =IF($B14=1,LARGE(データ入力!$B$12:$B$211,$A14),0) -> 36.9 | D14: =IF($B14=1,IFERROR(INDEX(データ入力!$A$12:$A$211,MATCH($C14,データ入力!$B$12:$B$211,0)),""),"") -> 1972 | E14: =IF($B14=1,1-$A14/(データ入力!$B$8+1),0) -> 0.89473684 | F14: =IF($B14=1,(データ入力!$B$8+1)/$A14,"") -> 9.5 | G14: =IF($B14=1,-LN(-LN($E14)),0) -> 2.1961944 | H14: =IF($B14=1,LN(-LN($E14)),0) -> -2.1961944 | I14: =IF($B14=1,IFERROR($C14-($N$10+$N$9*$G14),""),"") -> -0.28294576 | J14: =IF($B14=1,IFERROR($C14-($N$21-$N$26*EXP(-$G14/$N$24)),""),"") -> -0.30182536 | M14: 尺度母数 α (℃) | N14: =IFERROR(STDEV(データ入力!$B$12:$B$211)*SQRT(6)/PI(),"") -> 1.1724328 | T14: =IFERROR($R$6+($A14-1)*$R$5,"") -> 42.95 | U14: =IFERROR(SUMPRODUCT($B$7:$B$206,LN($T14-$C$7:$C$206)),"") -> 152.63623 | V14: =IFERROR(SUMPRODUCT($B$7:$B$206,LN($T14-$C$7:$C$206),LN($T14-$C$7:$C$206)),"") -> 314.1318 | W14: =IFERROR(SUMPRODUCT($B$7:$B$206,LN($T14-$C$7:$C$206),$H$7:$H$206),"") -> -65.7778 | X14: =IFERROR((データ入力!$B$8*W14-U14*$N$22)/SQRT((データ入力!$B$8*V14-U14^2)*(データ入力!$B$8*$N$23-$N$22^2)),-1) -> 0.99010129 | Z14: =IFERROR($R$10+($A14-1)*$R$9,"") -> 58.985176 | AA14: =IFERROR(SUMPRODUCT($B$7:$B$206,LN($Z14-$C$7:$C$206)),"") -> 237.74192 | AB14: =IFERROR(SUMPRODUCT($B$7:$B$206,LN($Z14-$C$7:$C$206),LN($Z14-$C$7:$C$206)),"") -> 753.92533 | AC14: =IFERROR(SUMPRODUCT($B$7:$B$206,LN($Z14-$C$7:$C$206),$H$7:$H$206),"") -> -126.44653 | AD14: =IFERROR((データ入力!$B$8*AC14-AA14*$N$22)/SQRT((データ入力!$B$8*AB14-AA14^2)*(データ入力!$B$8*$N$23-$N$22^2)),-1) -> 0.99702661 | AF14: -0.6 | AG14: =IFERROR($N$10+$N$9*$AF14,"") -> 33.686746 | AH14: =IFERROR($N$21-$N$26*EXP(-$AF14/$N$24),"") -> 33.644621 | AI14: =IFERROR(1/(1-EXP(-EXP(-$AF14))),"") -> 1.1928659
A15: 9 | B15: =IF($A15<=データ入力!$B$8,1,0) -> 1 | C15: =IF($B15=1,LARGE(データ入力!$B$12:$B$211,$A15),0) -> 36.9 | D15: =IF($B15=1,IFERROR(INDEX(データ入力!$A$12:$A$211,MATCH($C15,データ入力!$B$12:$B$211,0)),""),"") -> 1972 | E15: =IF($B15=1,1-$A15/(データ入力!$B$8+1),0) -> 0.88157895 | F15: =IF($B15=1,(データ入力!$B$8+1)/$A15,"") -> 8.4444444 | G15: =IF($B15=1,-LN(-LN($E15)),0) -> 2.0711502 | H15: =IF($B15=1,LN(-LN($E15)),0) -> -2.0711502 | I15: =IF($B15=1,IFERROR($C15-($N$10+$N$9*$G15),""),"") -> -0.12659779 | J15: =IF($B15=1,IFERROR($C15-($N$21-$N$26*EXP(-$G15/$N$24)),""),"") -> -0.15375669 | M15: 位置母数 β (℃) | N15: =IFERROR(AVERAGE(データ入力!$B$12:$B$211)-0.5772*N14,"") -> 34.455272 | T15: =IFERROR($R$6+($A15-1)*$R$5,"") -> 43.45 | U15: =IFERROR(SUMPRODUCT($B$7:$B$206,LN($T15-$C$7:$C$206)),"") -> 157.49288 | V15: =IFERROR(SUMPRODUCT($B$7:$B$206,LN($T15-$C$7:$C$206),LN($T15-$C$7:$C$206)),"") -> 333.73146 | W15: =IFERROR(SUMPRODUCT($B$7:$B$206,LN($T15-$C$7:$C$206),$H$7:$H$206),"") -> -69.81936 | X15: =IFERROR((データ入力!$B$8*W15-U15*$N$22)/SQRT((データ入力!$B$8*V15-U15^2)*(データ入力!$B$8*$N$23-$N$22^2)),-1) -> 0.99148802 | Z15: =IFERROR($R$10+($A15-1)*$R$9,"") -> 58.990201 | AA15: =IFERROR(SUMPRODUCT($B$7:$B$206,LN($Z15-$C$7:$C$206)),"") -> 237.75779 | AB15: =IFERROR(SUMPRODUCT($B$7:$B$206,LN($Z15-$C$7:$C$206),LN($Z15-$C$7:$C$206)),"") -> 754.02577 | AC15: =IFERROR(SUMPRODUCT($B$7:$B$206,LN($Z15-$C$7:$C$206),$H$7:$H$206),"") -> -126.45659 | AD15: =IFERROR((データ入力!$B$8*AC15-AA15*$N$22)/SQRT((データ入力!$B$8*AB15-AA15^2)*(データ入力!$B$8*$N$23-$N$22^2)),-1) -> 0.99702662 | AF15: -0.4 | AG15: =IFERROR($N$10+$N$9*$AF15,"") -> 33.936815 | AH15: =IFERROR($N$21-$N$26*EXP(-$AF15/$N$24),"") -> 33.916928 | AI15: =IFERROR(1/(1-EXP(-EXP(-$AF15))),"") -> 1.290259
A16: 10 | B16: =IF($A16<=データ入力!$B$8,1,0) -> 1 | C16: =IF($B16=1,LARGE(データ入力!$B$12:$B$211,$A16),0) -> 36.9 | D16: =IF($B16=1,IFERROR(INDEX(データ入力!$A$12:$A$211,MATCH($C16,データ入力!$B$12:$B$211,0)),""),"") -> 1972 | E16: =IF($B16=1,1-$A16/(データ入力!$B$8+1),0) -> 0.86842105 | F16: =IF($B16=1,(データ入力!$B$8+1)/$A16,"") -> 7.6 | G16: =IF($B16=1,-LN(-LN($E16)),0) -> 1.9584381 | H16: =IF($B16=1,LN(-LN($E16)),0) -> -1.9584381 | I16: =IF($B16=1,IFERROR($C16-($N$10+$N$9*$G16),""),"") -> 0.014330937 | J16: =IF($B16=1,IFERROR($C16-($N$21-$N$26*EXP(-$G16/$N$24)),""),"") -> -0.019447149 | T16: =IFERROR($R$6+($A16-1)*$R$5,"") -> 43.95 | U16: =IFERROR(SUMPRODUCT($B$7:$B$206,LN($T16-$C$7:$C$206)),"") -> 162.0392 | V16: =IFERROR(SUMPRODUCT($B$7:$B$206,LN($T16-$C$7:$C$206),LN($T16-$C$7:$C$206)),"") -> 352.71494 | W16: =IFERROR(SUMPRODUCT($B$7:$B$206,LN($T16-$C$7:$C$206),$H$7:$H$206),"") -> -73.503552 | X16: =IFERROR((データ入力!$B$8*W16-U16*$N$22)/SQRT((データ入力!$B$8*V16-U16^2)*(データ入力!$B$8*$N$23-$N$22^2)),-1) -> 0.99254539 | Z16: =IFERROR($R$10+($A16-1)*$R$9,"") -> 58.995226 | AA16: =IFERROR(SUMPRODUCT($B$7:$B$206,LN($Z16-$C$7:$C$206)),"") -> 237.77365 | AB16: =IFERROR(SUMPRODUCT($B$7:$B$206,LN($Z16-$C$7:$C$206),LN($Z16-$C$7:$C$206)),"") -> 754.1262 | AC16: =IFERROR(SUMPRODUCT($B$7:$B$206,LN($Z16-$C$7:$C$206),$H$7:$H$206),"") -> -126.46665 | AD16: =IFERROR((データ入力!$B$8*AC16-AA16*$N$22)/SQRT((データ入力!$B$8*AB16-AA16^2)*(データ入力!$B$8*$N$23-$N$22^2)),-1) -> 0.99702663 | AF16: -0.2 | AG16: =IFERROR($N$10+$N$9*$AF16,"") -> 34.186883 | AH16: =IFERROR($N$21-$N$26*EXP(-$AF16/$N$24),"") -> 34.186363 | AI16: =IFERROR(1/(1-EXP(-EXP(-$AF16))),"") -> 1.4180703
A17: 11 | B17: =IF($A17<=データ入力!$B$8,1,0) -> 1 | C17: =IF($B17=1,LARGE(データ入力!$B$12:$B$211,$A17),0) -> 36.8 | D17: =IF($B17=1,IFERROR(INDEX(データ入力!$A$12:$A$211,MATCH($C17,データ入力!$B$12:$B$211,0)),""),"") -> 1992 | E17: =IF($B17=1,1-$A17/(データ入力!$B$8+1),0) -> 0.85526316 | F17: =IF($B17=1,(データ入力!$B$8+1)/$A17,"") -> 6.9090909 | G17: =IF($B17=1,-LN(-LN($E17)),0) -> 1.8556833 | H17: =IF($B17=1,LN(-LN($E17)),0) -> -1.8556833 | I17: =IF($B17=1,IFERROR($C17-($N$10+$N$9*$G17),""),"") -> 0.042809568 | J17: =IF($B17=1,IFERROR($C17-($N$21-$N$26*EXP(-$G17/$N$24)),""),"") -> 0.0036982442 | M17: 【3】ワイブル分布（第III種極値分布・上限型）★主結果 | T17: =IFERROR($R$6+($A17-1)*$R$5,"") -> 44.45 | U17: =IFERROR(SUMPRODUCT($B$7:$B$206,LN($T17-$C$7:$C$206)),"") -> 166.31453 | V17: =IFERROR(SUMPRODUCT($B$7:$B$206,LN($T17-$C$7:$C$206),LN($T17-$C$7:$C$206)),"") -> 371.11859 | W17: =IFERROR(SUMPRODUCT($B$7:$B$206,LN($T17-$C$7:$C$206),$H$7:$H$206),"") -> -76.889543 | X17: =IFERROR((データ入力!$B$8*W17-U17*$N$22)/SQRT((データ入力!$B$8*V17-U17^2)*(データ入力!$B$8*$N$23-$N$22^2)),-1) -> 0.99336736 | Z17: =IFERROR($R$10+($A17-1)*$R$9,"") -> 59.000251 | AA17: =IFERROR(SUMPRODUCT($B$7:$B$206,LN($Z17-$C$7:$C$206)),"") -> 237.78951 | AB17: =IFERROR(SUMPRODUCT($B$7:$B$206,LN($Z17-$C$7:$C$206),LN($Z17-$C$7:$C$206)),"") -> 754.22661 | AC17: =IFERROR(SUMPRODUCT($B$7:$B$206,LN($Z17-$C$7:$C$206),$H$7:$H$206),"") -> -126.4767 | AD17: =IFERROR((データ入力!$B$8*AC17-AA17*$N$22)/SQRT((データ入力!$B$8*AB17-AA17^2)*(データ入力!$B$8*$N$23-$N$22^2)),-1) -> 0.99702664 | AF17: 0 | AG17: =IFERROR($N$10+$N$9*$AF17,"") -> 34.436951 | AH17: =IFERROR($N$21-$N$26*EXP(-$AF17/$N$24),"") -> 34.452957 | AI17: =IFERROR(1/(1-EXP(-EXP(-$AF17))),"") -> 1.5819767
A18: 12 | B18: =IF($A18<=データ入力!$B$8,1,0) -> 1 | C18: =IF($B18=1,LARGE(データ入力!$B$12:$B$211,$A18),0) -> 36.8 | D18: =IF($B18=1,IFERROR(INDEX(データ入力!$A$12:$A$211,MATCH($C18,データ入力!$B$12:$B$211,0)),""),"") -> 1992 | E18: =IF($B18=1,1-$A18/(データ入力!$B$8+1),0) -> 0.84210526 | F18: =IF($B18=1,(データ入力!$B$8+1)/$A18,"") -> 6.3333333 | G18: =IF($B18=1,-LN(-LN($E18)),0) -> 1.7611318 | H18: =IF($B18=1,LN(-LN($E18)),0) -> -1.7611318 | I18: =IF($B18=1,IFERROR($C18-($N$10+$N$9*$G18),""),"") -> 0.16103135 | J18: =IF($B18=1,IFERROR($C18-($N$21-$N$26*EXP(-$G18/$N$24)),""),"") -> 0.11760663 | M18: F(x)=exp[−((ω−x)/a)^k] ln(−ln F)=k·ln(ω−x)−k·ln a | T18: =IFERROR($R$6+($A18-1)*$R$5,"") -> 44.95 | U18: =IFERROR(SUMPRODUCT($B$7:$B$206,LN($T18-$C$7:$C$206)),"") -> 170.35075 | V18: =IFERROR(SUMPRODUCT($B$7:$B$206,LN($T18-$C$7:$C$206),LN($T18-$C$7:$C$206)),"") -> 388.97734 | W18: =IFERROR(SUMPRODUCT($B$7:$B$206,LN($T18-$C$7:$C$206),$H$7:$H$206),"") -> -80.022606 | X18: =IFERROR((データ入力!$B$8*W18-U18*$N$22)/SQRT((データ入力!$B$8*V18-U18^2)*(データ入力!$B$8*$N$23-$N$22^2)),-1) -> 0.99401651 | Z18: =IFERROR($R$10+($A18-1)*$R$9,"") -> 59.005276 | AA18: =IFERROR(SUMPRODUCT($B$7:$B$206,LN($Z18-$C$7:$C$206)),"") -> 237.80536 | AB18: =IFERROR(SUMPRODUCT($B$7:$B$206,LN($Z18-$C$7:$C$206),LN($Z18-$C$7:$C$206)),"") -> 754.32701 | AC18: =IFERROR(SUMPRODUCT($B$7:$B$206,LN($Z18-$C$7:$C$206),$H$7:$H$206),"") -> -126.48675 | AD18: =IFERROR((データ入力!$B$8*AC18-AA18*$N$22)/SQRT((データ入力!$B$8*AB18-AA18^2)*(データ入力!$B$8*$N$23-$N$22^2)),-1) -> 0.99702665 | AF18: 0.2 | AG18: =IFERROR($N$10+$N$9*$AF18,"") -> 34.68702 | AH18: =IFERROR($N$21-$N$26*EXP(-$AF18/$N$24),"") -> 34.71674 | AI18: =IFERROR(1/(1-EXP(-EXP(-$AF18))),"") -> 1.78888
A19: 13 | B19: =IF($A19<=データ入力!$B$8,1,0) -> 1 | C19: =IF($B19=1,LARGE(データ入力!$B$12:$B$211,$A19),0) -> 36.5 | D19: =IF($B19=1,IFERROR(INDEX(データ入力!$A$12:$A$211,MATCH($C19,データ入力!$B$12:$B$211,0)),""),"") -> 2003 | E19: =IF($B19=1,1-$A19/(データ入力!$B$8+1),0) -> 0.82894737 | F19: =IF($B19=1,(データ入力!$B$8+1)/$A19,"") -> 5.8461538 | G19: =IF($B19=1,-LN(-LN($E19)),0) -> 1.6734506 | H19: =IF($B19=1,LN(-LN($E19)),0) -> -1.6734506 | I19: =IF($B19=1,IFERROR($C19-($N$10+$N$9*$G19),""),"") -> -0.029337215 | J19: =IF($B19=1,IFERROR($C19-($N$21-$N$26*EXP(-$G19/$N$24)),""),"") -> -0.076250525 | M19: Σ ln(ω−x) | N19: =IFERROR(SUMPRODUCT($B$7:$B$206,LN($N$21-$C$7:$C$206)),"") -> 239.24968 | T19: =IFERROR($R$6+($A19-1)*$R$5,"") -> 45.45 | U19: =IFERROR(SUMPRODUCT($B$7:$B$206,LN($T19-$C$7:$C$206)),"") -> 174.17421 | V19: =IFERROR(SUMPRODUCT($B$7:$B$206,LN($T19-$C$7:$C$206),LN($T19-$C$7:$C$206)),"") -> 406.32398 | W19: =IFERROR(SUMPRODUCT($B$7:$B$206,LN($T19-$C$7:$C$206),$H$7:$H$206),"") -> -82.938247 | X19: =IFERROR((データ入力!$B$8*W19-U19*$N$22)/SQRT((データ入力!$B$8*V19-U19^2)*(データ入力!$B$8*$N$23-$N$22^2)),-1) -> 0.99453594 | Z19: =IFERROR($R$10+($A19-1)*$R$9,"") -> 59.010302 | AA19: =IFERROR(SUMPRODUCT($B$7:$B$206,LN($Z19-$C$7:$C$206)),"") -> 237.82121 | AB19: =IFERROR(SUMPRODUCT($B$7:$B$206,LN($Z19-$C$7:$C$206),LN($Z19-$C$7:$C$206)),"") -> 754.42739 | AC19: =IFERROR(SUMPRODUCT($B$7:$B$206,LN($Z19-$C$7:$C$206),$H$7:$H$206),"") -> -126.4968 | AD19: =IFERROR((データ入力!$B$8*AC19-AA19*$N$22)/SQRT((データ入力!$B$8*AB19-AA19^2)*(データ入力!$B$8*$N$23-$N$22^2)),-1) -> 0.99702666 | AF19: 0.4 | AG19: =IFERROR($N$10+$N$9*$AF19,"") -> 34.937088 | AH19: =IFERROR($N$21-$N$26*EXP(-$AF19/$N$24),"") -> 34.977741 | AI19: =IFERROR(1/(1-EXP(-EXP(-$AF19))),"") -> 2.0472708
A20: 14 | B20: =IF($A20<=データ入力!$B$8,1,0) -> 1 | C20: =IF($B20=1,LARGE(データ入力!$B$12:$B$211,$A20),0) -> 36.4 | D20: =IF($B20=1,IFERROR(INDEX(データ入力!$A$12:$A$211,MATCH($C20,データ入力!$B$12:$B$211,0)),""),"") -> 1997 | E20: =IF($B20=1,1-$A20/(データ入力!$B$8+1),0) -> 0.81578947 | F20: =IF($B20=1,(データ入力!$B$8+1)/$A20,"") -> 5.4285714 | G20: =IF($B20=1,-LN(-LN($E20)),0) -> 1.5916031 | H20: =IF($B20=1,LN(-LN($E20)),0) -> -1.5916031 | I20: =IF($B20=1,IFERROR($C20-($N$10+$N$9*$G20),""),"") -> -0.026999831 | J20: =IF($B20=1,IFERROR($C20-($N$21-$N$26*EXP(-$G20/$N$24)),""),"") -> -0.076723466 | M20: Σ [ln(ω−x)]² | N20: =IFERROR(SUMPRODUCT($B$7:$B$206,LN($N$21-$C$7:$C$206),LN($N$21-$C$7:$C$206)),"") -> 763.50201 | T20: =IFERROR($R$6+($A20-1)*$R$5,"") -> 45.95 | U20: =IFERROR(SUMPRODUCT($B$7:$B$206,LN($T20-$C$7:$C$206)),"") -> 177.80693 | V20: =IFERROR(SUMPRODUCT($B$7:$B$206,LN($T20-$C$7:$C$206),LN($T20-$C$7:$C$206)),"") -> 423.18901 | W20: =IFERROR(SUMPRODUCT($B$7:$B$206,LN($T20-$C$7:$C$206),$H$7:$H$206),"") -> -85.664879 | X20: =IFERROR((データ入力!$B$8*W20-U20*$N$22)/SQRT((データ入力!$B$8*V20-U20^2)*(データ入力!$B$8*$N$23-$N$22^2)),-1) -> 0.99495617 | Z20: =IFERROR($R$10+($A20-1)*$R$9,"") -> 59.015327 | AA20: =IFERROR(SUMPRODUCT($B$7:$B$206,LN($Z20-$C$7:$C$206)),"") -> 237.83706 | AB20: =IFERROR(SUMPRODUCT($B$7:$B$206,LN($Z20-$C$7:$C$206),LN($Z20-$C$7:$C$206)),"") -> 754.52776 | AC20: =IFERROR(SUMPRODUCT($B$7:$B$206,LN($Z20-$C$7:$C$206),$H$7:$H$206),"") -> -126.50684 | AD20: =IFERROR((データ入力!$B$8*AC20-AA20*$N$22)/SQRT((データ入力!$B$8*AB20-AA20^2)*(データ入力!$B$8*$N$23-$N$22^2)),-1) -> 0.99702666 | AF20: 0.6 | AG20: =IFERROR($N$10+$N$9*$AF20,"") -> 35.187157 | AH20: =IFERROR($N$21-$N$26*EXP(-$AF20/$N$24),"") -> 35.235989 | AI20: =IFERROR(1/(1-EXP(-EXP(-$AF20))),"") -> 2.3676252
A21: 15 | B21: =IF($A21<=データ入力!$B$8,1,0) -> 1 | C21: =IF($B21=1,LARGE(データ入力!$B$12:$B$211,$A21),0) -> 36.3 | D21: =IF($B21=1,IFERROR(INDEX(データ入力!$A$12:$A$211,MATCH($C21,データ入力!$B$12:$B$211,0)),""),"") -> 1994 | E21: =IF($B21=1,1-$A21/(データ入力!$B$8+1),0) -> 0.80263158 | F21: =IF($B21=1,(データ入力!$B$8+1)/$A21,"") -> 5.0666667 | G21: =IF($B21=1,-LN(-LN($E21)),0) -> 1.5147667 | H21: =IF($B21=1,LN(-LN($E21)),0) -> -1.5147667 | I21: =IF($B21=1,IFERROR($C21-($N$10+$N$9*$G21),""),"") -> -0.030927989 | J21: =IF($B21=1,IFERROR($C21-($N$21-$N$26*EXP(-$G21/$N$24)),""),"") -> -0.082896128 | M21: 上限母数 ω (℃) | N21: =IFERROR(INDEX($Z$7:$Z$206,MATCH(MAX($AD$7:$AD$206),$AD$7:$AD$206,0)),"") -> 59.467588 | T21: =IFERROR($R$6+($A21-1)*$R$5,"") -> 46.45 | U21: =IFERROR(SUMPRODUCT($B$7:$B$206,LN($T21-$C$7:$C$206)),"") -> 181.26758 | V21: =IFERROR(SUMPRODUCT($B$7:$B$206,LN($T21-$C$7:$C$206),LN($T21-$C$7:$C$206)),"") -> 439.60058 | W21: =IFERROR(SUMPRODUCT($B$7:$B$206,LN($T21-$C$7:$C$206),$H$7:$H$206),"") -> -88.225619 | X21: =IFERROR((データ入力!$B$8*W21-U21*$N$22)/SQRT((データ入力!$B$8*V21-U21^2)*(データ入力!$B$8*$N$23-$N$22^2)),-1) -> 0.99529933 | Z21: =IFERROR($R$10+($A21-1)*$R$9,"") -> 59.020352 | AA21: =IFERROR(SUMPRODUCT($B$7:$B$206,LN($Z21-$C$7:$C$206)),"") -> 237.8529 | AB21: =IFERROR(SUMPRODUCT($B$7:$B$206,LN($Z21-$C$7:$C$206),LN($Z21-$C$7:$C$206)),"") -> 754.62811 | AC21: =IFERROR(SUMPRODUCT($B$7:$B$206,LN($Z21-$C$7:$C$206),$H$7:$H$206),"") -> -126.51689 | AD21: =IFERROR((データ入力!$B$8*AC21-AA21*$N$22)/SQRT((データ入力!$B$8*AB21-AA21^2)*(データ入力!$B$8*$N$23-$N$22^2)),-1) -> 0.99702667 | AF21: 0.8 | AG21: =IFERROR($N$10+$N$9*$AF21,"") -> 35.437225 | AH21: =IFERROR($N$21-$N$26*EXP(-$AF21/$N$24),"") -> 35.491515 | AI21: =IFERROR(1/(1-EXP(-EXP(-$AF21))),"") -> 2.7628596
A22: 16 | B22: =IF($A22<=データ入力!$B$8,1,0) -> 1 | C22: =IF($B22=1,LARGE(データ入力!$B$12:$B$211,$A22),0) -> 36.2 | D22: =IF($B22=1,IFERROR(INDEX(データ入力!$A$12:$A$211,MATCH($C22,データ入力!$B$12:$B$211,0)),""),"") -> 2013 | E22: =IF($B22=1,1-$A22/(データ入力!$B$8+1),0) -> 0.78947368 | F22: =IF($B22=1,(データ入力!$B$8+1)/$A22,"") -> 4.75 | G22: =IF($B22=1,-LN(-LN($E22)),0) -> 1.4422775 | H22: =IF($B22=1,LN(-LN($E22)),0) -> -1.4422775 | I22: =IF($B22=1,IFERROR($C22-($N$10+$N$9*$G22),""),"") -> -0.040291668 | J22: =IF($B22=1,IFERROR($C22-($N$21-$N$26*EXP(-$G22/$N$24)),""),"") -> -0.094026317 | M22: Σ y | N22: =SUMPRODUCT($B$7:$B$206,$H$7:$H$206) -> -41.691505 | T22: =IFERROR($R$6+($A22-1)*$R$5,"") -> 46.95 | U22: =IFERROR(SUMPRODUCT($B$7:$B$206,LN($T22-$C$7:$C$206)),"") -> 184.57215 | V22: =IFERROR(SUMPRODUCT($B$7:$B$206,LN($T22-$C$7:$C$206),LN($T22-$C$7:$C$206)),"") -> 455.58463 | W22: =IFERROR(SUMPRODUCT($B$7:$B$206,LN($T22-$C$7:$C$206),$H$7:$H$206),"") -> -90.639548 | X22: =IFERROR((データ入力!$B$8*W22-U22*$N$22)/SQRT((データ入力!$B$8*V22-U22^2)*(データ入力!$B$8*$N$23-$N$22^2)),-1) -> 0.99558178 | Z22: =IFERROR($R$10+($A22-1)*$R$9,"") -> 59.025377 | AA22: =IFERROR(SUMPRODUCT($B$7:$B$206,LN($Z22-$C$7:$C$206)),"") -> 237.86874 | AB22: =IFERROR(SUMPRODUCT($B$7:$B$206,LN($Z22-$C$7:$C$206),LN($Z22-$C$7:$C$206)),"") -> 754.72846 | AC22: =IFERROR(SUMPRODUCT($B$7:$B$206,LN($Z22-$C$7:$C$206),$H$7:$H$206),"") -> -126.52693 | AD22: =IFERROR((データ入力!$B$8*AC22-AA22*$N$22)/SQRT((データ入力!$B$8*AB22-AA22^2)*(データ入力!$B$8*$N$23-$N$22^2)),-1) -> 0.99702668 | AF22: 1 | AG22: =IFERROR($N$10+$N$9*$AF22,"") -> 35.687294 | AH22: =IFERROR($N$21-$N$26*EXP(-$AF22/$N$24),"") -> 35.744346 | AI22: =IFERROR(1/(1-EXP(-EXP(-$AF22))),"") -> 3.2488695
A23: 17 | B23: =IF($A23<=データ入力!$B$8,1,0) -> 1 | C23: =IF($B23=1,LARGE(データ入力!$B$12:$B$211,$A23),0) -> 36.1 | D23: =IF($B23=1,IFERROR(INDEX(データ入力!$A$12:$A$211,MATCH($C23,データ入力!$B$12:$B$211,0)),""),"") -> 1998 | E23: =IF($B23=1,1-$A23/(データ入力!$B$8+1),0) -> 0.77631579 | F23: =IF($B23=1,(データ入力!$B$8+1)/$A23,"") -> 4.4705882 | G23: =IF($B23=1,-LN(-LN($E23)),0) -> 1.3735918 | H23: =IF($B23=1,LN(-LN($E23)),0) -> -1.3735918 | I23: =IF($B23=1,IFERROR($C23-($N$10+$N$9*$G23),""),"") -> -0.054411083 | J23: =IF($B23=1,IFERROR($C23-($N$21-$N$26*EXP(-$G23/$N$24)),""),"") -> -0.10950391 | M23: Σ y² | N23: =SUMPRODUCT($B$7:$B$206,$H$7:$H$206,$H$7:$H$206) -> 129.35073 | T23: =IFERROR($R$6+($A23-1)*$R$5,"") -> 47.45 | U23: =IFERROR(SUMPRODUCT($B$7:$B$206,LN($T23-$C$7:$C$206)),"") -> 187.73442 | V23: =IFERROR(SUMPRODUCT($B$7:$B$206,LN($T23-$C$7:$C$206),LN($T23-$C$7:$C$206)),"") -> 471.16505 | W23: =IFERROR(SUMPRODUCT($B$7:$B$206,LN($T23-$C$7:$C$206),$H$7:$H$206),"") -> -92.922609 | X23: =IFERROR((データ入力!$B$8*W23-U23*$N$22)/SQRT((データ入力!$B$8*V23-U23^2)*(データ入力!$B$8*$N$23-$N$22^2)),-1) -> 0.99581585 | Z23: =IFERROR($R$10+($A23-1)*$R$9,"") -> 59.030402 | AA23: =IFERROR(SUMPRODUCT($B$7:$B$206,LN($Z23-$C$7:$C$206)),"") -> 237.88458 | AB23: =IFERROR(SUMPRODUCT($B$7:$B$206,LN($Z23-$C$7:$C$206),LN($Z23-$C$7:$C$206)),"") -> 754.82878 | AC23: =IFERROR(SUMPRODUCT($B$7:$B$206,LN($Z23-$C$7:$C$206),$H$7:$H$206),"") -> -126.53697 | AD23: =IFERROR((データ入力!$B$8*AC23-AA23*$N$22)/SQRT((データ入力!$B$8*AB23-AA23^2)*(データ入力!$B$8*$N$23-$N$22^2)),-1) -> 0.99702669 | AF23: 1.2 | AG23: =IFERROR($N$10+$N$9*$AF23,"") -> 35.937362 | AH23: =IFERROR($N$21-$N$26*EXP(-$AF23/$N$24),"") -> 35.994511 | AI23: =IFERROR(1/(1-EXP(-EXP(-$AF23))),"") -> 3.8451786
A24: 18 | B24: =IF($A24<=データ入力!$B$8,1,0) -> 1 | C24: =IF($B24=1,LARGE(データ入力!$B$12:$B$211,$A24),0) -> 36.1 | D24: =IF($B24=1,IFERROR(INDEX(データ入力!$A$12:$A$211,MATCH($C24,データ入力!$B$12:$B$211,0)),""),"") -> 1998 | E24: =IF($B24=1,1-$A24/(データ入力!$B$8+1),0) -> 0.76315789 | F24: =IF($B24=1,(データ入力!$B$8+1)/$A24,"") -> 4.2222222 | G24: =IF($B24=1,-LN(-LN($E24)),0) -> 1.3082586 | H24: =IF($B24=1,LN(-LN($E24)),0) -> -1.3082586 | I24: =IF($B24=1,IFERROR($C24-($N$10+$N$9*$G24),""),"") -> 0.027277761 | J24: =IF($B24=1,IFERROR($C24-($N$21-$N$26*EXP(-$G24/$N$24)),""),"") -> -0.028820881 | M24: 形状母数 k | N24: =IFERROR((データ入力!$B$8*SUMPRODUCT($B$7:$B$206,LN($N$21-$C$7:$C$206),$H$7:$H$206)-N19*N22)/(データ入力!$B$8*N20-N19^2),"") -> 18.865914 | T24: =IFERROR($R$6+($A24-1)*$R$5,"") -> 47.95 | U24: =IFERROR(SUMPRODUCT($B$7:$B$206,LN($T24-$C$7:$C$206)),"") -> 190.76638 | V24: =IFERROR(SUMPRODUCT($B$7:$B$206,LN($T24-$C$7:$C$206),LN($T24-$C$7:$C$206)),"") -> 486.36383 | W24: =IFERROR(SUMPRODUCT($B$7:$B$206,LN($T24-$C$7:$C$206),$H$7:$H$206),"") -> -95.088264 | X24: =IFERROR((データ入力!$B$8*W24-U24*$N$22)/SQRT((データ入力!$B$8*V24-U24^2)*(データ入力!$B$8*$N$23-$N$22^2)),-1) -> 0.99601094 | Z24: =IFERROR($R$10+($A24-1)*$R$9,"") -> 59.035427 | AA24: =IFERROR(SUMPRODUCT($B$7:$B$206,LN($Z24-$C$7:$C$206)),"") -> 237.90041 | AB24: =IFERROR(SUMPRODUCT($B$7:$B$206,LN($Z24-$C$7:$C$206),LN($Z24-$C$7:$C$206)),"") -> 754.92909 | AC24: =IFERROR(SUMPRODUCT($B$7:$B$206,LN($Z24-$C$7:$C$206),$H$7:$H$206),"") -> -126.547 | AD24: =IFERROR((データ入力!$B$8*AC24-AA24*$N$22)/SQRT((データ入力!$B$8*AB24-AA24^2)*(データ入力!$B$8*$N$23-$N$22^2)),-1) -> 0.9970267 | AF24: 1.4 | AG24: =IFERROR($N$10+$N$9*$AF24,"") -> 36.18743 | AH24: =IFERROR($N$21-$N$26*EXP(-$AF24/$N$24),"") -> 36.242037 | AI24: =IFERROR(1/(1-EXP(-EXP(-$AF24))),"") -> 4.5757289
A25: 19 | B25: =IF($A25<=データ入力!$B$8,1,0) -> 1 | C25: =IF($B25=1,LARGE(データ入力!$B$12:$B$211,$A25),0) -> 36 | D25: =IF($B25=1,IFERROR(INDEX(データ入力!$A$12:$A$211,MATCH($C25,データ入力!$B$12:$B$211,0)),""),"") -> 1950 | E25: =IF($B25=1,1-$A25/(データ入力!$B$8+1),0) -> 0.75 | F25: =IF($B25=1,(データ入力!$B$8+1)/$A25,"") -> 4 | G25: =IF($B25=1,-LN(-LN($E25)),0) -> 1.2458993 | H25: =IF($B25=1,LN(-LN($E25)),0) -> -1.2458993 | I25: =IF($B25=1,IFERROR($C25-($N$10+$N$9*$G25),""),"") -> 0.0052481938 | J25: =IF($B25=1,IFERROR($C25-($N$21-$N$26*EXP(-$G25/$N$24)),""),"") -> -0.051549425 | M25: 切片 −k·ln a | N25: =IFERROR((N22-N24*N19)/データ入力!$B$8,"") -> -60.738073 | T25: =IFERROR($R$6+($A25-1)*$R$5,"") -> 48.45 | U25: =IFERROR(SUMPRODUCT($B$7:$B$206,LN($T25-$C$7:$C$206)),"") -> 193.67856 | V25: =IFERROR(SUMPRODUCT($B$7:$B$206,LN($T25-$C$7:$C$206),LN($T25-$C$7:$C$206)),"") -> 501.20123 | W25: =IFERROR(SUMPRODUCT($B$7:$B$206,LN($T25-$C$7:$C$206),$H$7:$H$206),"") -> -97.147992 | X25: =IFERROR((データ入力!$B$8*W25-U25*$N$22)/SQRT((データ入力!$B$8*V25-U25^2)*(データ入力!$B$8*$N$23-$N$22^2)),-1) -> 0.99617432 | Z25: =IFERROR($R$10+($A25-1)*$R$9,"") -> 59.040452 | AA25: =IFERROR(SUMPRODUCT($B$7:$B$206,LN($Z25-$C$7:$C$206)),"") -> 237.91624 | AB25: =IFERROR(SUMPRODUCT($B$7:$B$206,LN($Z25-$C$7:$C$206),LN($Z25-$C$7:$C$206)),"") -> 755.02939 | AC25: =IFERROR(SUMPRODUCT($B$7:$B$206,LN($Z25-$C$7:$C$206),$H$7:$H$206),"") -> -126.55704 | AD25: =IFERROR((データ入力!$B$8*AC25-AA25*$N$22)/SQRT((データ入力!$B$8*AB25-AA25^2)*(データ入力!$B$8*$N$23-$N$22^2)),-1) -> 0.99702671 | AF25: 1.6 | AG25: =IFERROR($N$10+$N$9*$AF25,"") -> 36.437499 | AH25: =IFERROR($N$21-$N$26*EXP(-$AF25/$N$24),"") -> 36.486954 | AI25: =IFERROR(1/(1-EXP(-EXP(-$AF25))),"") -> 5.4698457
A26: 20 | B26: =IF($A26<=データ入力!$B$8,1,0) -> 1 | C26: =IF($B26=1,LARGE(データ入力!$B$12:$B$211,$A26),0) -> 36 | D26: =IF($B26=1,IFERROR(INDEX(データ入力!$A$12:$A$211,MATCH($C26,データ入力!$B$12:$B$211,0)),""),"") -> 1950 | E26: =IF($B26=1,1-$A26/(データ入力!$B$8+1),0) -> 0.73684211 | F26: =IF($B26=1,(データ入力!$B$8+1)/$A26,"") -> 3.8 | G26: =IF($B26=1,-LN(-LN($E26)),0) -> 1.186193 | H26: =IF($B26=1,LN(-LN($E26)),0) -> -1.186193 | I26: =IF($B26=1,IFERROR($C26-($N$10+$N$9*$G26),""),"") -> 0.079901557 | J26: =IF($B26=1,IFERROR($C26-($N$21-$N$26*EXP(-$G26/$N$24)),""),"") -> 0.022674427 | M26: 尺度母数 a (℃) | N26: =IFERROR(EXP(-N25/N24),"") -> 25.014631 | T26: =IFERROR($R$6+($A26-1)*$R$5,"") -> 48.95 | U26: =IFERROR(SUMPRODUCT($B$7:$B$206,LN($T26-$C$7:$C$206)),"") -> 196.48021 | V26: =IFERROR(SUMPRODUCT($B$7:$B$206,LN($T26-$C$7:$C$206),LN($T26-$C$7:$C$206)),"") -> 515.69596 | W26: =IFERROR(SUMPRODUCT($B$7:$B$206,LN($T26-$C$7:$C$206),$H$7:$H$206),"") -> -99.111657 | X26: =IFERROR((データ入力!$B$8*W26-U26*$N$22)/SQRT((データ入力!$B$8*V26-U26^2)*(データ入力!$B$8*$N$23-$N$22^2)),-1) -> 0.99631172 | Z26: =IFERROR($R$10+($A26-1)*$R$9,"") -> 59.045477 | AA26: =IFERROR(SUMPRODUCT($B$7:$B$206,LN($Z26-$C$7:$C$206)),"") -> 237.93207 | AB26: =IFERROR(SUMPRODUCT($B$7:$B$206,LN($Z26-$C$7:$C$206),LN($Z26-$C$7:$C$206)),"") -> 755.12967 | AC26: =IFERROR(SUMPRODUCT($B$7:$B$206,LN($Z26-$C$7:$C$206),$H$7:$H$206),"") -> -126.56707 | AD26: =IFERROR((データ入力!$B$8*AC26-AA26*$N$22)/SQRT((データ入力!$B$8*AB26-AA26^2)*(データ入力!$B$8*$N$23-$N$22^2)),-1) -> 0.99702672 | AF26: 1.8 | AG26: =IFERROR($N$10+$N$9*$AF26,"") -> 36.687567 | AH26: =IFERROR($N$21-$N$26*EXP(-$AF26/$N$24),"") -> 36.729288 | AI26: =IFERROR(1/(1-EXP(-EXP(-$AF26))),"") -> 6.5634161
A27: 21 | B27: =IF($A27<=データ入力!$B$8,1,0) -> 1 | C27: =IF($B27=1,LARGE(データ入力!$B$12:$B$211,$A27),0) -> 35.9 | D27: =IF($B27=1,IFERROR(INDEX(データ入力!$A$12:$A$211,MATCH($C27,データ入力!$B$12:$B$211,0)),""),"") -> 2019 | E27: =IF($B27=1,1-$A27/(データ入力!$B$8+1),0) -> 0.72368421 | F27: =IF($B27=1,(データ入力!$B$8+1)/$A27,"") -> 3.6190476 | G27: =IF($B27=1,-LN(-LN($E27)),0) -> 1.1288649 | H27: =IF($B27=1,LN(-LN($E27)),0) -> -1.1288649 | I27: =IF($B27=1,IFERROR($C27-($N$10+$N$9*$G27),""),"") -> 0.051581323 | J27: =IF($B27=1,IFERROR($C27-($N$21-$N$26*EXP(-$G27/$N$24)),""),"") -> -0.0058368158 | M27: 相関係数 r | N27: =IFERROR((データ入力!$B$8*SUMPRODUCT($B$7:$B$206,LN($N$21-$C$7:$C$206),$H$7:$H$206)-N19*N22)/SQRT((データ入力!$B$8*N20-N19^2)*(データ入力!$B$8*N23-N22^2)),"") -> 0.99702707 | T27: =IFERROR($R$6+($A27-1)*$R$5,"") -> 49.45 | U27: =IFERROR(SUMPRODUCT($B$7:$B$206,LN($T27-$C$7:$C$206)),"") -> 199.17955 | V27: =IFERROR(SUMPRODUCT($B$7:$B$206,LN($T27-$C$7:$C$206),LN($T27-$C$7:$C$206)),"") -> 529.86528 | W27: =IFERROR(SUMPRODUCT($B$7:$B$206,LN($T27-$C$7:$C$206),$H$7:$H$206),"") -> -100.98781 | X27: =IFERROR((データ入力!$B$8*W27-U27*$N$22)/SQRT((データ入力!$B$8*V27-U27^2)*(データ入力!$B$8*$N$23-$N$22^2)),-1) -> 0.99642765 | Z27: =IFERROR($R$10+($A27-1)*$R$9,"") -> 59.050503 | AA27: =IFERROR(SUMPRODUCT($B$7:$B$206,LN($Z27-$C$7:$C$206)),"") -> 237.94789 | AB27: =IFERROR(SUMPRODUCT($B$7:$B$206,LN($Z27-$C$7:$C$206),LN($Z27-$C$7:$C$206)),"") -> 755.22994 | AC27: =IFERROR(SUMPRODUCT($B$7:$B$206,LN($Z27-$C$7:$C$206),$H$7:$H$206),"") -> -126.5771 | AD27: =IFERROR((データ入力!$B$8*AC27-AA27*$N$22)/SQRT((データ入力!$B$8*AB27-AA27^2)*(データ入力!$B$8*$N$23-$N$22^2)),-1) -> 0.99702673 | AF27: 2 | AG27: =IFERROR($N$10+$N$9*$AF27,"") -> 36.937636 | AH27: =IFERROR($N$21-$N$26*EXP(-$AF27/$N$24),"") -> 36.969066 | AI27: =IFERROR(1/(1-EXP(-EXP(-$AF27))),"") -> 7.9003306
A28: 22 | B28: =IF($A28<=データ入力!$B$8,1,0) -> 1 | C28: =IF($B28=1,LARGE(データ入力!$B$12:$B$211,$A28),0) -> 35.8 | D28: =IF($B28=1,IFERROR(INDEX(データ入力!$A$12:$A$211,MATCH($C28,データ入力!$B$12:$B$211,0)),""),"") -> 2006 | E28: =IF($B28=1,1-$A28/(データ入力!$B$8+1),0) -> 0.71052632 | F28: =IF($B28=1,(データ入力!$B$8+1)/$A28,"") -> 3.4545455 | G28: =IF($B28=1,-LN(-LN($E28)),0) -> 1.0736779 | H28: =IF($B28=1,LN(-LN($E28)),0) -> -1.0736779 | I28: =IF($B28=1,IFERROR($C28-($N$10+$N$9*$G28),""),"") -> 0.020583931 | J28: =IF($B28=1,IFERROR($C28-($N$21-$N$26*EXP(-$G28/$N$24)),""),"") -> -0.036812562 | M28: 分布形の判定 | N28: =IF(データ入力!$B$8<10,"― 標本数が不足しています（n≧10が必要）",IF(N21="","―",IF(N21>=$R$7-$R$5,"⚠ ωが探索上限に達しています：分布はグンベル(k→∞)に漸近。グンベルの値を採用してください",IF(N24>50,"△ k>50：実質的にグンベル分布に近い形です。グンベルの値と比較してください","○ 上限のあるワイブル形として推定（ω−標本最大値="&TEXT(N21-MAX(データ入力!$B$12:$B$211),"0.0")&"℃、k="&TEXT(N24,"0.0")&"）")))) -> ○ 上限のあるワイブル形として推定（ω−標本最大値=20.1℃、k=18.9） | T28: =IFERROR($R$6+($A28-1)*$R$5,"") -> 49.95 | U28: =IFERROR(SUMPRODUCT($B$7:$B$206,LN($T28-$C$7:$C$206)),"") -> 201.78388 | V28: =IFERROR(SUMPRODUCT($B$7:$B$206,LN($T28-$C$7:$C$206),LN($T28-$C$7:$C$206)),"") -> 543.72518 | W28: =IFERROR(SUMPRODUCT($B$7:$B$206,LN($T28-$C$7:$C$206),$H$7:$H$206),"") -> -102.78389 | X28: =IFERROR((データ入力!$B$8*W28-U28*$N$22)/SQRT((データ入力!$B$8*V28-U28^2)*(データ入力!$B$8*$N$23-$N$22^2)),-1) -> 0.99652572 | Z28: =IFERROR($R$10+($A28-1)*$R$9,"") -> 59.055528 | AA28: =IFERROR(SUMPRODUCT($B$7:$B$206,LN($Z28-$C$7:$C$206)),"") -> 237.96371 | AB28: =IFERROR(SUMPRODUCT($B$7:$B$206,LN($Z28-$C$7:$C$206),LN($Z28-$C$7:$C$206)),"") -> 755.33019 | AC28: =IFERROR(SUMPRODUCT($B$7:$B$206,LN($Z28-$C$7:$C$206),$H$7:$H$206),"") -> -126.58713 | AD28: =IFERROR((データ入力!$B$8*AC28-AA28*$N$22)/SQRT((データ入力!$B$8*AB28-AA28^2)*(データ入力!$B$8*$N$23-$N$22^2)),-1) -> 0.99702673 | AF28: 2.2 | AG28: =IFERROR($N$10+$N$9*$AF28,"") -> 37.187704 | AH28: =IFERROR($N$21-$N$26*EXP(-$AF28/$N$24),"") -> 37.206316 | AI28: =IFERROR(1/(1-EXP(-EXP(-$AF28))),"") -> 9.5342452
A29: 23 | B29: =IF($A29<=データ入力!$B$8,1,0) -> 1 | C29: =IF($B29=1,LARGE(データ入力!$B$12:$B$211,$A29),0) -> 35.7 | D29: =IF($B29=1,IFERROR(INDEX(データ入力!$A$12:$A$211,MATCH($C29,データ入力!$B$12:$B$211,0)),""),"") -> 1970 | E29: =IF($B29=1,1-$A29/(データ入力!$B$8+1),0) -> 0.69736842 | F29: =IF($B29=1,(データ入力!$B$8+1)/$A29,"") -> 3.3043478 | G29: =IF($B29=1,-LN(-LN($E29)),0) -> 1.0204258 | H29: =IF($B29=1,LN(-LN($E29)),0) -> -1.0204258 | I29: =IF($B29=1,IFERROR($C29-($N$10+$N$9*$G29),""),"") -> -0.012832779 | J29: =IF($B29=1,IFERROR($C29-($N$21-$N$26*EXP(-$G29/$N$24)),""),"") -> -0.070016697 | T29: =IFERROR($R$6+($A29-1)*$R$5,"") -> 50.45 | U29: =IFERROR(SUMPRODUCT($B$7:$B$206,LN($T29-$C$7:$C$206)),"") -> 204.29977 | V29: =IFERROR(SUMPRODUCT($B$7:$B$206,LN($T29-$C$7:$C$206),LN($T29-$C$7:$C$206)),"") -> 557.29048 | W29: =IFERROR(SUMPRODUCT($B$7:$B$206,LN($T29-$C$7:$C$206),$H$7:$H$206),"") -> -104.50644 | X29: =IFERROR((データ入力!$B$8*W29-U29*$N$22)/SQRT((データ入力!$B$8*V29-U29^2)*(データ入力!$B$8*$N$23-$N$22^2)),-1) -> 0.99660885 | Z29: =IFERROR($R$10+($A29-1)*$R$9,"") -> 59.060553 | AA29: =IFERROR(SUMPRODUCT($B$7:$B$206,LN($Z29-$C$7:$C$206)),"") -> 237.97953 | AB29: =IFERROR(SUMPRODUCT($B$7:$B$206,LN($Z29-$C$7:$C$206),LN($Z29-$C$7:$C$206)),"") -> 755.43043 | AC29: =IFERROR(SUMPRODUCT($B$7:$B$206,LN($Z29-$C$7:$C$206),$H$7:$H$206),"") -> -126.59715 | AD29: =IFERROR((データ入力!$B$8*AC29-AA29*$N$22)/SQRT((データ入力!$B$8*AB29-AA29^2)*(データ入力!$B$8*$N$23-$N$22^2)),-1) -> 0.99702674 | AF29: 2.4 | AG29: =IFERROR($N$10+$N$9*$AF29,"") -> 37.437772 | AH29: =IFERROR($N$21-$N$26*EXP(-$AF29/$N$24),"") -> 37.441064 | AI29: =IFERROR(1/(1-EXP(-EXP(-$AF29))),"") -> 11.530735
A30: 24 | B30: =IF($A30<=データ入力!$B$8,1,0) -> 1 | C30: =IF($B30=1,LARGE(データ入力!$B$12:$B$211,$A30),0) -> 35.6 | D30: =IF($B30=1,IFERROR(INDEX(データ入力!$A$12:$A$211,MATCH($C30,データ入力!$B$12:$B$211,0)),""),"") -> 1956 | E30: =IF($B30=1,1-$A30/(データ入力!$B$8+1),0) -> 0.68421053 | F30: =IF($B30=1,(データ入力!$B$8+1)/$A30,"") -> 3.1666667 | G30: =IF($B30=1,-LN(-LN($E30)),0) -> 0.96892803 | H30: =IF($B30=1,LN(-LN($E30)),0) -> -0.96892803 | I30: =IF($B30=1,IFERROR($C30-($N$10+$N$9*$G30),""),"") -> -0.048442931 | J30: =IF($B30=1,IFERROR($C30-($N$21-$N$26*EXP(-$G30/$N$24)),""),"") -> -0.1052417 | T30: =IFERROR($R$6+($A30-1)*$R$5,"") -> 50.95 | U30: =IFERROR(SUMPRODUCT($B$7:$B$206,LN($T30-$C$7:$C$206)),"") -> 206.73308 | V30: =IFERROR(SUMPRODUCT($B$7:$B$206,LN($T30-$C$7:$C$206),LN($T30-$C$7:$C$206)),"") -> 570.57493 | W30: =IFERROR(SUMPRODUCT($B$7:$B$206,LN($T30-$C$7:$C$206),$H$7:$H$206),"") -> -106.16123 | X30: =IFERROR((データ入力!$B$8*W30-U30*$N$22)/SQRT((データ入力!$B$8*V30-U30^2)*(データ入力!$B$8*$N$23-$N$22^2)),-1) -> 0.99667941 | Z30: =IFERROR($R$10+($A30-1)*$R$9,"") -> 59.065578 | AA30: =IFERROR(SUMPRODUCT($B$7:$B$206,LN($Z30-$C$7:$C$206)),"") -> 237.99534 | AB30: =IFERROR(SUMPRODUCT($B$7:$B$206,LN($Z30-$C$7:$C$206),LN($Z30-$C$7:$C$206)),"") -> 755.53065 | AC30: =IFERROR(SUMPRODUCT($B$7:$B$206,LN($Z30-$C$7:$C$206),$H$7:$H$206),"") -> -126.60717 | AD30: =IFERROR((データ入力!$B$8*AC30-AA30*$N$22)/SQRT((データ入力!$B$8*AB30-AA30^2)*(データ入力!$B$8*$N$23-$N$22^2)),-1) -> 0.99702675 | AF30: 2.6 | AG30: =IFERROR($N$10+$N$9*$AF30,"") -> 37.687841 | AH30: =IFERROR($N$21-$N$26*EXP(-$AF30/$N$24),"") -> 37.673337 | AI30: =IFERROR(1/(1-EXP(-EXP(-$AF30))),"") -> 13.969927
A31: 25 | B31: =IF($A31<=データ入力!$B$8,1,0) -> 1 | C31: =IF($B31=1,LARGE(データ入力!$B$12:$B$211,$A31),0) -> 35.6 | D31: =IF($B31=1,IFERROR(INDEX(データ入力!$A$12:$A$211,MATCH($C31,データ入力!$B$12:$B$211,0)),""),"") -> 1956 | E31: =IF($B31=1,1-$A31/(データ入力!$B$8+1),0) -> 0.67105263 | F31: =IF($B31=1,(データ入力!$B$8+1)/$A31,"") -> 3.04 | G31: =IF($B31=1,-LN(-LN($E31)),0) -> 0.9190252 | H31: =IF($B31=1,LN(-LN($E31)),0) -> -0.9190252 | I31: =IF($B31=1,IFERROR($C31-($N$10+$N$9*$G31),""),"") -> 0.013952681 | J31: =IF($B31=1,IFERROR($C31-($N$21-$N$26*EXP(-$G31/$N$24)),""),"") -> -0.042303958 | T31: =IFERROR($R$6+($A31-1)*$R$5,"") -> 51.45 | U31: =IFERROR(SUMPRODUCT($B$7:$B$206,LN($T31-$C$7:$C$206)),"") -> 209.08912 | V31: =IFERROR(SUMPRODUCT($B$7:$B$206,LN($T31-$C$7:$C$206),LN($T31-$C$7:$C$206)),"") -> 583.59131 | W31: =IFERROR(SUMPRODUCT($B$7:$B$206,LN($T31-$C$7:$C$206),$H$7:$H$206),"") -> -107.75338 | X31: =IFERROR((データ入力!$B$8*W31-U31*$N$22)/SQRT((データ入力!$B$8*V31-U31^2)*(データ入力!$B$8*$N$23-$N$22^2)),-1) -> 0.99673934 | Z31: =IFERROR($R$10+($A31-1)*$R$9,"") -> 59.070603 | AA31: =IFERROR(SUMPRODUCT($B$7:$B$206,LN($Z31-$C$7:$C$206)),"") -> 238.01115 | AB31: =IFERROR(SUMPRODUCT($B$7:$B$206,LN($Z31-$C$7:$C$206),LN($Z31-$C$7:$C$206)),"") -> 755.63086 | AC31: =IFERROR(SUMPRODUCT($B$7:$B$206,LN($Z31-$C$7:$C$206),$H$7:$H$206),"") -> -126.61719 | AD31: =IFERROR((データ入力!$B$8*AC31-AA31*$N$22)/SQRT((データ入力!$B$8*AB31-AA31^2)*(データ入力!$B$8*$N$23-$N$22^2)),-1) -> 0.99702676 | AF31: 2.8 | AG31: =IFERROR($N$10+$N$9*$AF31,"") -> 37.937909 | AH31: =IFERROR($N$21-$N$26*EXP(-$AF31/$N$24),"") -> 37.90316 | AI31: =IFERROR(1/(1-EXP(-EXP(-$AF31))),"") -> 16.949714
A32: 26 | B32: =IF($A32<=データ入力!$B$8,1,0) -> 1 | C32: =IF($B32=1,LARGE(データ入力!$B$12:$B$211,$A32),0) -> 35.5 | D32: =IF($B32=1,IFERROR(INDEX(データ入力!$A$12:$A$211,MATCH($C32,データ入力!$B$12:$B$211,0)),""),"") -> 1961 | E32: =IF($B32=1,1-$A32/(データ入力!$B$8+1),0) -> 0.65789474 | F32: =IF($B32=1,(データ入力!$B$8+1)/$A32,"") -> 2.9230769 | G32: =IF($B32=1,-LN(-LN($E32)),0) -> 0.87057592 | H32: =IF($B32=1,LN(-LN($E32)),0) -> -0.87057592 | I32: =IF($B32=1,IFERROR($C32-($N$10+$N$9*$G32),""),"") -> -0.025469149 | J32: =IF($B32=1,IFERROR($C32-($N$21-$N$26*EXP(-$G32/$N$24)),""),"") -> -0.081039966 | T32: =IFERROR($R$6+($A32-1)*$R$5,"") -> 51.95 | U32: =IFERROR(SUMPRODUCT($B$7:$B$206,LN($T32-$C$7:$C$206)),"") -> 211.37271 | V32: =IFERROR(SUMPRODUCT($B$7:$B$206,LN($T32-$C$7:$C$206),LN($T32-$C$7:$C$206)),"") -> 596.35155 | W32: =IFERROR(SUMPRODUCT($B$7:$B$206,LN($T32-$C$7:$C$206),$H$7:$H$206),"") -> -109.28743 | X32: =IFERROR((データ入力!$B$8*W32-U32*$N$22)/SQRT((データ入力!$B$8*V32-U32^2)*(データ入力!$B$8*$N$23-$N$22^2)),-1) -> 0.99679024 | Z32: =IFERROR($R$10+($A32-1)*$R$9,"") -> 59.075628 | AA32: =IFERROR(SUMPRODUCT($B$7:$B$206,LN($Z32-$C$7:$C$206)),"") -> 238.02696 | AB32: =IFERROR(SUMPRODUCT($B$7:$B$206,LN($Z32-$C$7:$C$206),LN($Z32-$C$7:$C$206)),"") -> 755.73106 | AC32: =IFERROR(SUMPRODUCT($B$7:$B$206,LN($Z32-$C$7:$C$206),$H$7:$H$206),"") -> -126.62721 | AD32: =IFERROR((データ入力!$B$8*AC32-AA32*$N$22)/SQRT((データ入力!$B$8*AB32-AA32^2)*(データ入力!$B$8*$N$23-$N$22^2)),-1) -> 0.99702677 | AF32: 3 | AG32: =IFERROR($N$10+$N$9*$AF32,"") -> 38.187978 | AH32: =IFERROR($N$21-$N$26*EXP(-$AF32/$N$24),"") -> 38.13056 | AI32: =IFERROR(1/(1-EXP(-EXP(-$AF32))),"") -> 20.589686
A33: 27 | B33: =IF($A33<=データ入力!$B$8,1,0) -> 1 | C33: =IF($B33=1,LARGE(データ入力!$B$12:$B$211,$A33),0) -> 35.5 | D33: =IF($B33=1,IFERROR(INDEX(データ入力!$A$12:$A$211,MATCH($C33,データ入力!$B$12:$B$211,0)),""),"") -> 1961 | E33: =IF($B33=1,1-$A33/(データ入力!$B$8+1),0) -> 0.64473684 | F33: =IF($B33=1,(データ入力!$B$8+1)/$A33,"") -> 2.8148148 | G33: =IF($B33=1,-LN(-LN($E33)),0) -> 0.82345397 | H33: =IF($B33=1,LN(-LN($E33)),0) -> -0.82345397 | I33: =IF($B33=1,IFERROR($C33-($N$10+$N$9*$G33),""),"") -> 0.033449417 | J33: =IF($B33=1,IFERROR($C33-($N$21-$N$26*EXP(-$G33/$N$24)),""),"") -> -0.021303251 | T33: =IFERROR($R$6+($A33-1)*$R$5,"") -> 52.45 | U33: =IFERROR(SUMPRODUCT($B$7:$B$206,LN($T33-$C$7:$C$206)),"") -> 213.58821 | V33: =IFERROR(SUMPRODUCT($B$7:$B$206,LN($T33-$C$7:$C$206),LN($T33-$C$7:$C$206)),"") -> 608.86674 | W33: =IFERROR(SUMPRODUCT($B$7:$B$206,LN($T33-$C$7:$C$206),$H$7:$H$206),"") -> -110.76746 | X33: =IFERROR((データ入力!$B$8*W33-U33*$N$22)/SQRT((データ入力!$B$8*V33-U33^2)*(データ入力!$B$8*$N$23-$N$22^2)),-1) -> 0.99683344 | Z33: =IFERROR($R$10+($A33-1)*$R$9,"") -> 59.080653 | AA33: =IFERROR(SUMPRODUCT($B$7:$B$206,LN($Z33-$C$7:$C$206)),"") -> 238.04276 | AB33: =IFERROR(SUMPRODUCT($B$7:$B$206,LN($Z33-$C$7:$C$206),LN($Z33-$C$7:$C$206)),"") -> 755.83124 | AC33: =IFERROR(SUMPRODUCT($B$7:$B$206,LN($Z33-$C$7:$C$206),$H$7:$H$206),"") -> -126.63722 | AD33: =IFERROR((データ入力!$B$8*AC33-AA33*$N$22)/SQRT((データ入力!$B$8*AB33-AA33^2)*(データ入力!$B$8*$N$23-$N$22^2)),-1) -> 0.99702678 | AF33: 3.2 | AG33: =IFERROR($N$10+$N$9*$AF33,"") -> 38.438046 | AH33: =IFERROR($N$21-$N$26*EXP(-$AF33/$N$24),"") -> 38.355562 | AI33: =IFERROR(1/(1-EXP(-EXP(-$AF33))),"") -> 25.035927
A34: 28 | B34: =IF($A34<=データ入力!$B$8,1,0) -> 1 | C34: =IF($B34=1,LARGE(データ入力!$B$12:$B$211,$A34),0) -> 35.5 | D34: =IF($B34=1,IFERROR(INDEX(データ入力!$A$12:$A$211,MATCH($C34,データ入力!$B$12:$B$211,0)),""),"") -> 1961 | E34: =IF($B34=1,1-$A34/(データ入力!$B$8+1),0) -> 0.63157895 | F34: =IF($B34=1,(データ入力!$B$8+1)/$A34,"") -> 2.7142857 | G34: =IF($B34=1,-LN(-LN($E34)),0) -> 0.77754598 | H34: =IF($B34=1,LN(-LN($E34)),0) -> -0.77754598 | I34: =IF($B34=1,IFERROR($C34-($N$10+$N$9*$G34),""),"") -> 0.090850105 | J34: =IF($B34=1,IFERROR($C34-($N$21-$N$26*EXP(-$G34/$N$24)),""),"") -> 0.037038173 | T34: =IFERROR($R$6+($A34-1)*$R$5,"") -> 52.95 | U34: =IFERROR(SUMPRODUCT($B$7:$B$206,LN($T34-$C$7:$C$206)),"") -> 215.7396 | V34: =IFERROR(SUMPRODUCT($B$7:$B$206,LN($T34-$C$7:$C$206),LN($T34-$C$7:$C$206)),"") -> 621.14727 | W34: =IFERROR(SUMPRODUCT($B$7:$B$206,LN($T34-$C$7:$C$206),$H$7:$H$206),"") -> -112.19714 | X34: =IFERROR((データ入力!$B$8*W34-U34*$N$22)/SQRT((データ入力!$B$8*V34-U34^2)*(データ入力!$B$8*$N$23-$N$22^2)),-1) -> 0.99687005 | Z34: =IFERROR($R$10+($A34-1)*$R$9,"") -> 59.085678 | AA34: =IFERROR(SUMPRODUCT($B$7:$B$206,LN($Z34-$C$7:$C$206)),"") -> 238.05856 | AB34: =IFERROR(SUMPRODUCT($B$7:$B$206,LN($Z34-$C$7:$C$206),LN($Z34-$C$7:$C$206)),"") -> 755.9314 | AC34: =IFERROR(SUMPRODUCT($B$7:$B$206,LN($Z34-$C$7:$C$206),$H$7:$H$206),"") -> -126.64724 | AD34: =IFERROR((データ入力!$B$8*AC34-AA34*$N$22)/SQRT((データ入力!$B$8*AB34-AA34^2)*(データ入力!$B$8*$N$23-$N$22^2)),-1) -> 0.99702678 | AF34: 3.4 | AG34: =IFERROR($N$10+$N$9*$AF34,"") -> 38.688115 | AH34: =IFERROR($N$21-$N$26*EXP(-$AF34/$N$24),"") -> 38.578191 | AI34: =IFERROR(1/(1-EXP(-EXP(-$AF34))),"") -> 30.466881
A35: 29 | B35: =IF($A35<=データ入力!$B$8,1,0) -> 1 | C35: =IF($B35=1,LARGE(データ入力!$B$12:$B$211,$A35),0) -> 35.3 | D35: =IF($B35=1,IFERROR(INDEX(データ入力!$A$12:$A$211,MATCH($C35,データ入力!$B$12:$B$211,0)),""),"") -> 1964 | E35: =IF($B35=1,1-$A35/(データ入力!$B$8+1),0) -> 0.61842105 | F35: =IF($B35=1,(データ入力!$B$8+1)/$A35,"") -> 2.6206897 | G35: =IF($B35=1,-LN(-LN($E35)),0) -> 0.73274963 | H35: =IF($B35=1,LN(-LN($E35)),0) -> -0.73274963 | I35: =IF($B35=1,IFERROR($C35-($N$10+$N$9*$G35),""),"") -> -0.05313913 | J35: =IF($B35=1,IFERROR($C35-($N$21-$N$26*EXP(-$G35/$N$24)),""),"") -> -0.10589609 | T35: =IFERROR($R$6+($A35-1)*$R$5,"") -> 53.45 | U35: =IFERROR(SUMPRODUCT($B$7:$B$206,LN($T35-$C$7:$C$206)),"") -> 217.83052 | V35: =IFERROR(SUMPRODUCT($B$7:$B$206,LN($T35-$C$7:$C$206),LN($T35-$C$7:$C$206)),"") -> 633.20286 | W35: =IFERROR(SUMPRODUCT($B$7:$B$206,LN($T35-$C$7:$C$206),$H$7:$H$206),"") -> -113.57977 | X35: =IFERROR((データ入力!$B$8*W35-U35*$N$22)/SQRT((データ入力!$B$8*V35-U35^2)*(データ入力!$B$8*$N$23-$N$22^2)),-1) -> 0.99690099 | Z35: =IFERROR($R$10+($A35-1)*$R$9,"") -> 59.090704 | AA35: =IFERROR(SUMPRODUCT($B$7:$B$206,LN($Z35-$C$7:$C$206)),"") -> 238.07436 | AB35: =IFERROR(SUMPRODUCT($B$7:$B$206,LN($Z35-$C$7:$C$206),LN($Z35-$C$7:$C$206)),"") -> 756.03156 | AC35: =IFERROR(SUMPRODUCT($B$7:$B$206,LN($Z35-$C$7:$C$206),$H$7:$H$206),"") -> -126.65725 | AD35: =IFERROR((データ入力!$B$8*AC35-AA35*$N$22)/SQRT((データ入力!$B$8*AB35-AA35^2)*(データ入力!$B$8*$N$23-$N$22^2)),-1) -> 0.99702679 | AF35: 3.6 | AG35: =IFERROR($N$10+$N$9*$AF35,"") -> 38.938183 | AH35: =IFERROR($N$21-$N$26*EXP(-$AF35/$N$24),"") -> 38.798473 | AI35: =IFERROR(1/(1-EXP(-EXP(-$AF35))),"") -> 37.100511
A36: 30 | B36: =IF($A36<=データ入力!$B$8,1,0) -> 1 | C36: =IF($B36=1,LARGE(データ入力!$B$12:$B$211,$A36),0) -> 35.3 | D36: =IF($B36=1,IFERROR(INDEX(データ入力!$A$12:$A$211,MATCH($C36,データ入力!$B$12:$B$211,0)),""),"") -> 1964 | E36: =IF($B36=1,1-$A36/(データ入力!$B$8+1),0) -> 0.60526316 | F36: =IF($B36=1,(データ入力!$B$8+1)/$A36,"") -> 2.5333333 | G36: =IF($B36=1,-LN(-LN($E36)),0) -> 0.68897202 | H36: =IF($B36=1,LN(-LN($E36)),0) -> -0.68897202 | I36: =IF($B36=1,IFERROR($C36-($N$10+$N$9*$G36),""),"") -> 0.0015978586 | J36: =IF($B36=1,IFERROR($C36-($N$21-$N$26*EXP(-$G36/$N$24)),""),"") -> -0.04999705 | T36: =IFERROR($R$6+($A36-1)*$R$5,"") -> 53.95 | U36: =IFERROR(SUMPRODUCT($B$7:$B$206,LN($T36-$C$7:$C$206)),"") -> 219.86429 | V36: =IFERROR(SUMPRODUCT($B$7:$B$206,LN($T36-$C$7:$C$206),LN($T36-$C$7:$C$206)),"") -> 645.04261 | W36: =IFERROR(SUMPRODUCT($B$7:$B$206,LN($T36-$C$7:$C$206),$H$7:$H$206),"") -> -114.91833 | X36: =IFERROR((データ入力!$B$8*W36-U36*$N$22)/SQRT((データ入力!$B$8*V36-U36^2)*(データ入力!$B$8*$N$23-$N$22^2)),-1) -> 0.99692705 | Z36: =IFERROR($R$10+($A36-1)*$R$9,"") -> 59.095729 | AA36: =IFERROR(SUMPRODUCT($B$7:$B$206,LN($Z36-$C$7:$C$206)),"") -> 238.09015 | AB36: =IFERROR(SUMPRODUCT($B$7:$B$206,LN($Z36-$C$7:$C$206),LN($Z36-$C$7:$C$206)),"") -> 756.13169 | AC36: =IFERROR(SUMPRODUCT($B$7:$B$206,LN($Z36-$C$7:$C$206),$H$7:$H$206),"") -> -126.66725 | AD36: =IFERROR((データ入力!$B$8*AC36-AA36*$N$22)/SQRT((データ入力!$B$8*AB36-AA36^2)*(データ入力!$B$8*$N$23-$N$22^2)),-1) -> 0.9970268 | AF36: 3.8 | AG36: =IFERROR($N$10+$N$9*$AF36,"") -> 39.188251 | AH36: =IFERROR($N$21-$N$26*EXP(-$AF36/$N$24),"") -> 39.016431 | AI36: =IFERROR(1/(1-EXP(-EXP(-$AF36))),"") -> 45.203049
A37: 31 | B37: =IF($A37<=データ入力!$B$8,1,0) -> 1 | C37: =IF($B37=1,LARGE(データ入力!$B$12:$B$211,$A37),0) -> 35.3 | D37: =IF($B37=1,IFERROR(INDEX(データ入力!$A$12:$A$211,MATCH($C37,データ入力!$B$12:$B$211,0)),""),"") -> 1964 | E37: =IF($B37=1,1-$A37/(データ入力!$B$8+1),0) -> 0.59210526 | F37: =IF($B37=1,(データ入力!$B$8+1)/$A37,"") -> 2.4516129 | G37: =IF($B37=1,-LN(-LN($E37)),0) -> 0.64612839 | H37: =IF($B37=1,LN(-LN($E37)),0) -> -0.64612839 | I37: =IF($B37=1,IFERROR($C37-($N$10+$N$9*$G37),""),"") -> 0.055167052 | J37: =IF($B37=1,IFERROR($C37-($N$21-$N$26*EXP(-$G37/$N$24)),""),"") -> 0.0048351327 | T37: =IFERROR($R$6+($A37-1)*$R$5,"") -> 54.45 | U37: =IFERROR(SUMPRODUCT($B$7:$B$206,LN($T37-$C$7:$C$206)),"") -> 221.84399 | V37: =IFERROR(SUMPRODUCT($B$7:$B$206,LN($T37-$C$7:$C$206),LN($T37-$C$7:$C$206)),"") -> 656.67505 | W37: =IFERROR(SUMPRODUCT($B$7:$B$206,LN($T37-$C$7:$C$206),$H$7:$H$206),"") -> -116.21554 | X37: =IFERROR((データ入力!$B$8*W37-U37*$N$22)/SQRT((データ入力!$B$8*V37-U37^2)*(データ入力!$B$8*$N$23-$N$22^2)),-1) -> 0.99694889 | Z37: =IFERROR($R$10+($A37-1)*$R$9,"") -> 59.100754 | AA37: =IFERROR(SUMPRODUCT($B$7:$B$206,LN($Z37-$C$7:$C$206)),"") -> 238.10594 | AB37: =IFERROR(SUMPRODUCT($B$7:$B$206,LN($Z37-$C$7:$C$206),LN($Z37-$C$7:$C$206)),"") -> 756.23181 | AC37: =IFERROR(SUMPRODUCT($B$7:$B$206,LN($Z37-$C$7:$C$206),$H$7:$H$206),"") -> -126.67726 | AD37: =IFERROR((データ入力!$B$8*AC37-AA37*$N$22)/SQRT((データ入力!$B$8*AB37-AA37^2)*(データ入力!$B$8*$N$23-$N$22^2)),-1) -> 0.99702681 | AF37: 4 | AG37: =IFERROR($N$10+$N$9*$AF37,"") -> 39.43832 | AH37: =IFERROR($N$21-$N$26*EXP(-$AF37/$N$24),"") -> 39.232092 | AI37: =IFERROR(1/(1-EXP(-EXP(-$AF37))),"") -> 55.099676
A38: 32 | B38: =IF($A38<=データ入力!$B$8,1,0) -> 1 | C38: =IF($B38=1,LARGE(データ入力!$B$12:$B$211,$A38),0) -> 35.3 | D38: =IF($B38=1,IFERROR(INDEX(データ入力!$A$12:$A$211,MATCH($C38,データ入力!$B$12:$B$211,0)),""),"") -> 1964 | E38: =IF($B38=1,1-$A38/(データ入力!$B$8+1),0) -> 0.57894737 | F38: =IF($B38=1,(データ入力!$B$8+1)/$A38,"") -> 2.375 | G38: =IF($B38=1,-LN(-LN($E38)),0) -> 0.604141 | H38: =IF($B38=1,LN(-LN($E38)),0) -> -0.604141 | I38: =IF($B38=1,IFERROR($C38-($N$10+$N$9*$G38),""),"") -> 0.10766566 | J38: =IF($B38=1,IFERROR($C38-($N$21-$N$26*EXP(-$G38/$N$24)),""),"") -> 0.058692437 | T38: =IFERROR($R$6+($A38-1)*$R$5,"") -> 54.95 | U38: =IFERROR(SUMPRODUCT($B$7:$B$206,LN($T38-$C$7:$C$206)),"") -> 223.77243 | V38: =IFERROR(SUMPRODUCT($B$7:$B$206,LN($T38-$C$7:$C$206),LN($T38-$C$7:$C$206)),"") -> 668.10822 | W38: =IFERROR(SUMPRODUCT($B$7:$B$206,LN($T38-$C$7:$C$206),$H$7:$H$206),"") -> -117.47387 | X38: =IFERROR((データ入力!$B$8*W38-U38*$N$22)/SQRT((データ入力!$B$8*V38-U38^2)*(データ入力!$B$8*$N$23-$N$22^2)),-1) -> 0.99696707 | Z38: =IFERROR($R$10+($A38-1)*$R$9,"") -> 59.105779 | AA38: =IFERROR(SUMPRODUCT($B$7:$B$206,LN($Z38-$C$7:$C$206)),"") -> 238.12173 | AB38: =IFERROR(SUMPRODUCT($B$7:$B$206,LN($Z38-$C$7:$C$206),LN($Z38-$C$7:$C$206)),"") -> 756.33192 | AC38: =IFERROR(SUMPRODUCT($B$7:$B$206,LN($Z38-$C$7:$C$206),$H$7:$H$206),"") -> -126.68726 | AD38: =IFERROR((データ入力!$B$8*AC38-AA38*$N$22)/SQRT((データ入力!$B$8*AB38-AA38^2)*(データ入力!$B$8*$N$23-$N$22^2)),-1) -> 0.99702681 | AF38: 4.2 | AG38: =IFERROR($N$10+$N$9*$AF38,"") -> 39.688388 | AH38: =IFERROR($N$21-$N$26*EXP(-$AF38/$N$24),"") -> 39.445478 | AI38: =IFERROR(1/(1-EXP(-EXP(-$AF38))),"") -> 67.187581
